Workbook

Sheet GM
A2: 2019 MC Sales Target
B4: 40909 | C4: 40940 | D4: 40969 | E4: 41000 | F4: 41030 | G4: 41061 | H4: 41091 | I4: 41122 | J4: 41153 | K4: 41183 | L4: 41214 | M4: 41244 | O4: Q1 | P4: Q2 | Q4: Q3 | R4: Q4 | S4: Total
A5: AGM Goal | B5: 5200 | C5: 4750 | D5: 5300 | E5: 5150 | F5: 5650 | G5: 5400 | H5: 5225 | I5: 5150 | J5: 5150 | K5: 5600 | L5: 5700 | M5: 6225 | O5: =SUM(B5:D5) -> 15250 | P5: =SUM(E5:G5) -> 16200 | Q5: =SUM(H5:J5) -> 15525 | R5: =SUM(K5:M5) -> 17525 | S5: =SUM(O5:R5) -> 64500
O7: =O5/S5 -> 0.23643411 | P7: =P5/S5 -> 0.25116279 | Q7: =Q5/S5 -> 0.24069767 | R7: =R5/S5 -> 0.27170543
A9: Area | B9: 40909 | C9: 40940 | D9: 40969 | E9: 41000 | F9: 41030 | G9: 41061 | H9: 41091 | I9: 41122 | J9: 41153 | K9: 41183 | L9: 41214 | M9: 41244 | O9: Q1 | P9: Q2 | Q9: Q3 | R9: Q4 | S9: Total
A10: Area 1 (MC) | B10: ='A1'!B23 -> 540 | C10: ='A1'!C23 -> 472 | D10: ='A1'!D23 -> 568 | E10: ='A1'!E23 -> 524 | F10: ='A1'!F23 -> 586 | G10: ='A1'!G23 -> 550 | H10: ='A1'!H23 -> 516 | I10: ='A1'!I23 -> 498 | ... M10: ='A1'!M23 -> 651 | O10: =SUM(B10:D10) -> 1580 | P10: =SUM(E10:G10) -> 1660 | Q10: =SUM(H10:J10) -> 1468 | R10: =SUM(K10:M10) -> 1735 | S10: =SUM(O10:R10) -> 6443
A11: Area 2 (MC) | B11: ='A2'!B23 -> 568 | C11: ='A2'!C23 -> 479 | D11: ='A2'!D23 -> 575 | E11: ='A2'!E23 -> 557 | F11: ='A2'!F23 -> 579 | G11: ='A2'!G23 -> 571 | H11: ='A2'!H23 -> 464 | I11: ='A2'!I23 -> 458 | ... M11: ='A2'!M23 -> 668 | O11: =SUM(B11:D11) -> 1622 | P11: =SUM(E11:G11) -> 1707 | Q11: =SUM(H11:J11) -> 1462 | R11: =SUM(K11:M11) -> 1934 | S11: =SUM(O11:R11) -> 6725
A12: Area 3 (MC) | B12: ='A3'!B20 -> 386 | C12: ='A3'!C20 -> 340 | D12: ='A3'!D20 -> 370 | E12: ='A3'!E20 -> 382 | F12: ='A3'!F20 -> 390 | G12: ='A3'!G20 -> 378 | H12: ='A3'!H20 -> 354 | I12: ='A3'!I20 -> 345 | ... M12: ='A3'!M20 -> 420 | O12: =SUM(B12:D12) -> 1096 | P12: =SUM(E12:G12) -> 1150 | Q12: =SUM(H12:J12) -> 1044 | R12: =SUM(K12:M12) -> 1196 | S12: =SUM(O12:R12) -> 4486
A13: Area 4 (MC) | B13: ='A4'!B28 -> 694 | C13: ='A4'!C28 -> 610 | D13: ='A4'!D28 -> 691 | E13: ='A4'!E28 -> 657 | F13: ='A4'!F28 -> 757 | G13: ='A4'!G28 -> 764 | H13: ='A4'!H28 -> 764 | I13: ='A4'!I28 -> 755 | ... M13: ='A4'!M28 -> 869 | O13: =SUM(B13:D13) -> 1995 | P13: =SUM(E13:G13) -> 2178 | Q13: =SUM(H13:J13) -> 2253 | R13: =SUM(K13:M13) -> 2517 | S13: =SUM(O13:R13) -> 8943
A14: Area 5 (MC) | B14: ='A5'!B20 -> 548 | C14: ='A5'!C20 -> 445 | D14: ='A5'!D20 -> 521 | E14: ='A5'!E20 -> 457 | F14: ='A5'!F20 -> 540 | G14: ='A5'!G20 -> 500 | H14: ='A5'!H20 -> 422 | I14: ='A5'!I20 -> 404 | ... M14: ='A5'!M20 -> 628 | O14: =SUM(B14:D14) -> 1514 | P14: =SUM(E14:G14) -> 1497 | Q14: =SUM(H14:J14) -> 1272 | R14: =SUM(K14:M14) -> 1644 | S14: =SUM(O14:R14) -> 5927
A15: Area 6 (MC) | B15: ='A6'!B22 -> 271 | C15: ='A6'!C22 -> 257 | D15: ='A6'!D22 -> 311 | E15: ='A6'!E22 -> 306 | F15: ='A6'!F22 -> 326 | G15: ='A6'!G22 -> 296 | H15: ='A6'!H22 -> 282 | I15: ='A6'!I22 -> 256 | ... M15: ='A6'!M22 -> 326 | O15: =SUM(B15:D15) -> 839 | P15: =SUM(E15:G15) -> 928 | Q15: =SUM(H15:J15) -> 796 | R15: =SUM(K15:M15) -> 933 | S15: =SUM(O15:R15) -> 3496
A16: Area 7 (MC) | B16: ='A7'!B21 -> 560 | C16: ='A7'!C21 -> 508 | D16: ='A7'!D21 -> 536 | E16: ='A7'!E21 -> 505 | F16: ='A7'!F21 -> 578 | G16: ='A7'!G21 -> 530 | H16: ='A7'!H21 -> 530 | I16: ='A7'!I21 -> 525 | ... M16: ='A7'!M21 -> 625 | O16: =SUM(B16:D16) -> 1604 | P16: =SUM(E16:G16) -> 1613 | Q16: =SUM(H16:J16) -> 1560 | R16: =SUM(K16:M16) -> 1745 | S16: =SUM(O16:R16) -> 6522
A17: Area 8 (MC) | B17: ='A8'!B25 -> 431 | C17: ='A8'!C25 -> 428 | D17: ='A8'!D25 -> 485 | E17: ='A8'!E25 -> 505 | F17: ='A8'!F25 -> 572 | G17: ='A8'!G25 -> 560 | H17: ='A8'!H25 -> 546 | I17: ='A8'!I25 -> 540 | ... M17: ='A8'!M25 -> 586 | O17: =SUM(B17:D17) -> 1344 | P17: =SUM(E17:G17) -> 1637 | Q17: =SUM(H17:J17) -> 1603 | R17: =SUM(K17:M17) -> 1728 | S17: =SUM(O17:R17) -> 6312
A18: Area 9 (MC) | B18: ='A9'!B21 -> 500 | C18: ='A9'!C21 -> 460 | D18: ='A9'!D21 -> 500 | E18: ='A9'!E21 -> 460 | F18: ='A9'!F21 -> 500 | G18: ='A9'!G21 -> 480 | H18: ='A9'!H21 -> 530 | I18: ='A9'!I21 -> 515 | ... M18: ='A9'!M21 -> 486 | O18: =SUM(B18:D18) -> 1460 | P18: =SUM(E18:G18) -> 1440 | Q18: =SUM(H18:J18) -> 1561 | R18: =SUM(K18:M18) -> 1517 | S18: =SUM(O18:R18) -> 5978
A19: Area 10 (MC) | B19: ='A10'!B20 -> 310 | C19: ='A10'!C20 -> 310 | D19: ='A10'!D20 -> 340 | E19: ='A10'!E20 -> 300 | F19: ='A10'!F20 -> 350 | G19: ='A10'!G20 -> 330 | H19: ='A10'!H20 -> 339 | I19: ='A10'!I20 -> 320 | ... M19: ='A10'!M20 -> 360 | O19: =SUM(B19:D19) -> 960 | P19: =SUM(E19:G19) -> 980 | Q19: =SUM(H19:J19) -> 989 | R19: =SUM(K19:M19) -> 1030 | S19: =SUM(O19:R19) -> 3959
A20: Area 11 (MC) | B20: ='A11'!B19 -> 46 | C20: ='A11'!C19 -> 46 | D20: ='A11'!D19 -> 52 | E20: ='A11'!E19 -> 48 | F20: ='A11'!F19 -> 50 | G20: ='A11'!G19 -> 49 | H20: ='A11'!H19 -> 48 | I20: ='A11'!I19 -> 49 | ... M20: ='A11'!M19 -> 64 | O20: =SUM(B20:D20) -> 144 | P20: =SUM(E20:G20) -> 147 | Q20: =SUM(H20:J20) -> 145 | R20: =SUM(K20:M20) -> 175 | S20: =SUM(O20:R20) -> 611
A21: Area 12 (MC) | B21: ='A12'!B20 -> 300 | C21: ='A12'!C20 -> 267 | D21: ='A12'!D20 -> 295 | E21: ='A12'!E20 -> 251 | F21: ='A12'!F20 -> 327 | G21: ='A12'!G20 -> 313 | H21: ='A12'!H20 -> 288 | I21: ='A12'!I20 -> 274 | ... M21: ='A12'!M20 -> 340 | O21: =SUM(B21:D21) -> 862 | P21: =SUM(E21:G21) -> 891 | Q21: =SUM(H21:J21) -> 849 | R21: =SUM(K21:M21) -> 934 | S21: =SUM(O21:R21) -> 3536
A22: Area 13 (MC) | B22: ='A13'!B16 -> 23 | C22: ='A13'!C16 -> 42 | D22: ='A13'!D16 -> 45 | E22: ='A13'!E16 -> 43 | F22: ='A13'!F16 -> 56 | G22: ='A13'!G16 -> 48 | H22: ='A13'!H16 -> 49 | I22: ='A13'!I16 -> 51 | ... M22: ='A13'!M16 -> 63 | O22: =SUM(B22:D22) -> 110 | P22: =SUM(E22:G22) -> 147 | Q22: =SUM(H22:J22) -> 155 | R22: =SUM(K22:M22) -> 177 | S22: =SUM(O22:R22) -> 589
A23: Daet, Cam N. | B23: ='Daet CN'!B17 -> 0 | C23: ='Daet CN'!C17 -> 20 | D23: ='Daet CN'!D17 -> 20 | E23: ='Daet CN'!E17 -> 25 | F23: ='Daet CN'!F17 -> 25 | G23: ='Daet CN'!G17 -> 20 | H23: ='Daet CN'!H17 -> 40 | I23: ='Daet CN'!I17 -> 40 | ... M23: ='Daet CN'!M17 -> 80 | O23: =SUM(B23:D23) -> 40 | P23: =SUM(E23:G23) -> 70 | Q23: =SUM(H23:J23) -> 130 | R23: =SUM(K23:M23) -> 235 | S23: =SUM(O23:R23) -> 475
A24: TOTAL | B24: =SUM(B10:B22) -> 5177 | C24: =SUM(C10:C22) -> 4664 | D24: =SUM(D10:D22) -> 5289 | E24: =SUM(E10:E22) -> 4995 | F24: =SUM(F10:F22) -> 5611 | G24: =SUM(G10:G22) -> 5369 | H24: =SUM(H10:H22) -> 5132 | I24: =SUM(I10:I22) -> 4990 | ... M24: =SUM(M10:M22) -> 6086 | O24: =SUM(O10:O23) -> 15170 | P24: =SUM(P10:P23) -> 16045 | Q24: =SUM(Q10:Q23) -> 15287 | R24: =SUM(R10:R23) -> 17500 | S24: =SUM(O24:R24) -> 64002
M26: 2019 | O26: =O24/S24 -> 0.23702384 | P26: =P24/S24 -> 0.25069529 | Q26: =Q24/S24 -> 0.23885191 | R26: =R24/S24 -> 0.27342896 | S26: =SUM(O26:R26) -> 1
M28: 2018 | O28: 0.2382 | P28: 0.2527 | Q28: 0.2404 | R28: 0.2687 | S28: =SUM(O28:R28) -> 1
B31: PREPARED BY: | H31: APPROVED BY:
B34: ARNOLD L. GUILLEN | H34: GUANSON Y. LO
B35: GENERAL MANAGER-MC | H35: PRESIDENT
B38: NOTED BY:
B41: REX S. ADVERSALO
B42: GENERAL MANAGER-ADMIN

Sheet A1
A1: 2019 BRANCH HEAD GOAL: AREA 1
A3: BRANCHES | B3: 1ST QUARTER | E3: 2ND QUARTER | H3: 3RD QUARTER | K3: 4TH QUARTER | O3: GRAND TOTAL
B4: JAN | C4: FEB | D4: MAR | E4: APR | F4: MAY | G4: JUNE | H4: JUL | I4: AUG | J4: SEP | K4: OCT | L4: NOV | M4: DEC | O4: 1Q | P4: 2Q | Q4: 3Q | R4: 4Q | S4: TTL
A6: UEMI Vigan - Multi | B6: 86 | C6: 70 | D6: 89 | E6: 72 | F6: 78 | G6: 77 | H6: 82 | I6: 83 | J6: 65 | K6: 68 | L6: 70 | M6: 85 | O6: =SUM(B6:D6) -> 245 | P6: =SUM(E6:G6) -> 227 | Q6: =SUM(H6:J6) -> 230 | R6: =SUM(K6:M6) -> 223 | S6: =SUM(O6:R6) -> 925
A7: GMC Vigan - Honda | B7: 57 | C7: 45 | D7: 50 | E7: 48 | F7: 55 | G7: 55 | H7: 50 | I7: 45 | J7: 35 | K7: 45 | L7: 52 | M7: 68 | O7: =SUM(B7:D7) -> 152 | P7: =SUM(E7:G7) -> 158 | Q7: =SUM(H7:J7) -> 130 | R7: =SUM(K7:M7) -> 165 | S7: =SUM(O7:R7) -> 605
A8: UEMI Cabugao - Multi | B8: 67 | C8: 50 | D8: 71 | E8: 70 | F8: 78 | G8: 70 | H8: 60 | I8: 56 | J8: 50 | K8: 58 | L8: 60 | M8: 80 | O8: =SUM(B8:D8) -> 188 | P8: =SUM(E8:G8) -> 218 | Q8: =SUM(H8:J8) -> 166 | R8: =SUM(K8:M8) -> 198 | S8: =SUM(O8:R8) -> 770
A9: UEMI Laoag - Multi | B9: 40 | C9: 30 | D9: 34 | E9: 40 | F9: 40 | G9: 40 | H9: 32 | I9: 30 | J9: 30 | K9: 35 | L9: 30 | M9: 40 | O9: =SUM(B9:D9) -> 104 | P9: =SUM(E9:G9) -> 120 | Q9: =SUM(H9:J9) -> 92 | R9: =SUM(K9:M9) -> 105 | S9: =SUM(O9:R9) -> 421
A10: UEMI Laoag - Yamaha | B10: 46 | C10: 45 | D10: 54 | E10: 45 | F10: 47 | G10: 50 | H10: 39 | I10: 42 | J10: 38 | K10: 45 | L10: 42 | M10: 45 | O10: =SUM(B10:D10) -> 145 | P10: =SUM(E10:G10) -> 142 | Q10: =SUM(H10:J10) -> 119 | R10: =SUM(K10:M10) -> 132 | S10: =SUM(O10:R10) -> 538
A11: UEMI Bangued - Yamaha | B11: 43 | C11: 40 | D11: 45 | E11: 35 | F11: 50 | G11: 45 | H11: 42 | I11: 42 | J11: 35 | K11: 60 | L11: 60 | M11: 65 | O11: =SUM(B11:D11) -> 128 | P11: =SUM(E11:G11) -> 130 | Q11: =SUM(H11:J11) -> 119 | R11: =SUM(K11:M11) -> 185 | S11: =SUM(O11:R11) -> 562
A12: UEMI Bangued - Multi | B12: 40 | C12: 30 | D12: 35 | E12: 30 | F12: 45 | G12: 35 | H12: 30 | I12: 35 | J12: 35 | K12: 40 | L12: 48 | M12: 55 | O12: =SUM(B12:D12) -> 105 | P12: =SUM(E12:G12) -> 110 | Q12: =SUM(H12:J12) -> 100 | R12: =SUM(K12:M12) -> 143 | S12: =SUM(O12:R12) -> 458
A13: GMC Pasuquin - Multi | B13: 25 | C13: 25 | D13: 30 | E13: 30 | F13: 30 | G13: 32 | H13: 32 | I13: 27 | J13: 27 | K13: 31 | L13: 32 | M13: 32 | O13: =SUM(B13:D13) -> 80 | P13: =SUM(E13:G13) -> 92 | Q13: =SUM(H13:J13) -> 86 | R13: =SUM(K13:M13) -> 95 | S13: =SUM(O13:R13) -> 353
A14: UEMI Batac - Yamaha | B14: 40 | C14: 35 | D14: 50 | E14: 42 | F14: 49 | G14: 39 | H14: 40 | I14: 37 | J14: 38 | K14: 40 | L14: 45 | M14: 55 | O14: =SUM(B14:D14) -> 125 | P14: =SUM(E14:G14) -> 130 | Q14: =SUM(H14:J14) -> 115 | R14: =SUM(K14:M14) -> 140 | S14: =SUM(O14:R14) -> 510
A15: LGK San Nicolas - Honda | B15: 30 | C15: 25 | D15: 26 | E15: 25 | F15: 27 | G15: 26 | H15: 25 | I15: 25 | J15: 25 | K15: 26 | L15: 27 | M15: 30 | O15: =SUM(B15:D15) -> 81 | P15: =SUM(E15:G15) -> 78 | Q15: =SUM(H15:J15) -> 75 | R15: =SUM(K15:M15) -> 83 | S15: =SUM(O15:R15) -> 317
A16: MCC Batac - Honda | B16: 25 | C16: 25 | D16: 27 | E16: 28 | F16: 30 | G16: 25 | H16: 30 | I16: 25 | J16: 25 | K16: 27 | L16: 28 | M16: 32 | O16: =SUM(B16:D16) -> 77 | P16: =SUM(E16:G16) -> 83 | Q16: =SUM(H16:J16) -> 80 | R16: =SUM(K16:M16) -> 87 | S16: =SUM(O16:R16) -> 327
A17: UEMI Dingras - Multi | B17: 26 | C17: 27 | D17: 32 | E17: 29 | F17: 27 | G17: 26 | H17: 26 | I17: 25 | J17: 25 | K17: 28 | L17: 28 | M17: 30 | O17: =SUM(B17:D17) -> 85 | P17: =SUM(E17:G17) -> 82 | Q17: =SUM(H17:J17) -> 76 | R17: =SUM(K17:M17) -> 86 | S17: =SUM(O17:R17) -> 329
A18: UEMI San Nicolas - Yamaha | B18: 15 | C18: 25 | D18: 25 | E18: 30 | F18: 30 | G18: 30 | H18: 28 | I18: 26 | J18: 26 | K18: 30 | L18: 30 | M18: 35 | O18: =SUM(B18:D18) -> 65 | P18: =SUM(E18:G18) -> 90 | Q18: =SUM(H18:J18) -> 80 | R18: =SUM(K18:M18) -> 95 | S18: =SUM(O18:R18) -> 330
A22: TOTAL | B22: =SUM(B6:B21) -> 540 | C22: =SUM(C6:C21) -> 472 | D22: =SUM(D6:D21) -> 568 | E22: =SUM(E6:E21) -> 524 | F22: =SUM(F6:F21) -> 586 | G22: =SUM(G6:G21) -> 550 | H22: =SUM(H6:H21) -> 516 | I22: =SUM(I6:I21) -> 498 | ... M22: =SUM(M6:M21) -> 652 | O22: =SUM(B22:D22) -> 1580 | P22: =SUM(E22:G22) -> 1660 | Q22: =SUM(H22:J22) -> 1468 | R22: =SUM(K22:M22) -> 1737 | S22: =SUM(O22:R22) -> 6445
A23: AH Goal | B23: 540 | C23: 472 | D23: 568 | E23: 524 | F23: 586 | G23: 550 | H23: 516 | I23: 498 | J23: 454 | K23: 532 | L23: 552 | M23: 651 | O23: =SUM(B23:D23) -> 1580 | P23: =SUM(E23:G23) -> 1660 | Q23: =SUM(H23:J23) -> 1468 | R23: =SUM(K23:M23) -> 1735 | S23: =SUM(O23:R23) -> 6443
O24: =O22/S22 -> 0.24515128 | P24: =P22/S22 -> 0.257564 | Q24: =Q22/S22 -> 0.22777347 | R24: =R22/S22 -> 0.26951125 | S24: =SUM(O24:R24) -> 1 | U24: =S24 -> 1
O25: =O23/S23 -> 0.24522738 | P25: =P23/S23 -> 0.25764395 | Q25: =Q23/S23 -> 0.22784417 | R25: =R23/S23 -> 0.26928449 | S25: =SUM(O25:R25) -> 1
B28: PREPARED BY:
B31: ARNULFO GUILLEN
B32: GM-MC

Sheet A2
A1: 2019 BRANCH HEAD GOAL: AREA 2
A3: BRANCHES | B3: 1ST QUARTER | E3: 2ND QUARTER | H3: 3RD QUARTER | K3: 4TH QUARTER | O3: GRAND TOTAL
B4: JAN | C4: FEB | D4: MAR | E4: APR | F4: MAY | G4: JUNE | H4: JUL | I4: AUG | J4: SEP | K4: OCT | L4: NOV | M4: DEC | O4: 1Q | P4: 2Q | Q4: 3Q | R4: 4Q | S4: TTL
A6: LGK Candon - Honda | B6: 68 | C6: 60 | D6: 68 | E6: 65 | F6: 65 | G6: 62 | H6: 49 | I6: 49 | J6: 55 | K6: 65 | L6: 65 | M6: 70 | O6: =SUM(B6:D6) -> 196 | P6: =SUM(E6:G6) -> 192 | Q6: =SUM(H6:J6) -> 153 | R6: =SUM(K6:M6) -> 200 | S6: =SUM(O6:R6) -> 741
A7: GMC Baguio - Honda | B7: 64 | C7: 56 | D7: 63 | E7: 55 | F7: 56 | G7: 55 | H7: 51 | I7: 45 | J7: 45 | K7: 65 | L7: 65 | M7: 65 | O7: =SUM(B7:D7) -> 183 | P7: =SUM(E7:G7) -> 166 | Q7: =SUM(H7:J7) -> 141 | R7: =SUM(K7:M7) -> 195 | S7: =SUM(O7:R7) -> 685
A8: UEMI Narvacan - Multi | B8: 62 | C8: 60 | D8: 63 | E8: 60 | F8: 60 | G8: 60 | H8: 45 | I8: 45 | J8: 55 | K8: 62 | L8: 62 | M8: 65 | O8: =SUM(B8:D8) -> 185 | P8: =SUM(E8:G8) -> 180 | Q8: =SUM(H8:J8) -> 145 | R8: =SUM(K8:M8) -> 189 | S8: =SUM(O8:R8) -> 699
A9: GMC San Fernando - Honda | B9: 44 | C9: 33 | D9: 44 | E9: 32 | F9: 35 | G9: 35 | H9: 32 | I9: 32 | J9: 35 | K9: 45 | L9: 45 | M9: 46 | O9: =SUM(B9:D9) -> 121 | P9: =SUM(E9:G9) -> 102 | Q9: =SUM(H9:J9) -> 99 | R9: =SUM(K9:M9) -> 136 | S9: =SUM(O9:R9) -> 458
A10: MCC Tagudin - Honda | B10: 50 | C10: 35 | D10: 45 | E10: 52 | F10: 52 | G10: 52 | H10: 32 | I10: 32 | J10: 39 | K10: 55 | L10: 55 | M10: 55 | O10: =SUM(B10:D10) -> 130 | P10: =SUM(E10:G10) -> 156 | Q10: =SUM(H10:J10) -> 103 | R10: =SUM(K10:M10) -> 165 | S10: =SUM(O10:R10) -> 554
A11: UEMI Candon - Multi | B11: 40 | C11: 30 | D11: 42 | E11: 40 | F11: 45 | G11: 40 | H11: 30 | I11: 30 | J11: 40 | K11: 45 | L11: 45 | M11: 46 | O11: =SUM(B11:D11) -> 112 | P11: =SUM(E11:G11) -> 125 | Q11: =SUM(H11:J11) -> 100 | R11: =SUM(K11:M11) -> 136 | S11: =SUM(O11:R11) -> 473
A12: UEMI San Fernando - Yamaha | B12: 55 | C12: 40 | D12: 55 | E12: 54 | F12: 52 | G12: 52 | H12: 40 | I12: 40 | J12: 45 | K12: 55 | L12: 55 | M12: 65 | O12: =SUM(B12:D12) -> 150 | P12: =SUM(E12:G12) -> 158 | Q12: =SUM(H12:J12) -> 125 | R12: =SUM(K12:M12) -> 175 | S12: =SUM(O12:R12) -> 608
A13: UEMI La Trinidad - Yamaha | B13: 65 | C13: 55 | D13: 65 | E13: 65 | F13: 64 | G13: 64 | H13: 50 | I13: 50 | J13: 55 | K13: 65 | L13: 65 | M13: 65 | O13: =SUM(B13:D13) -> 185 | P13: =SUM(E13:G13) -> 193 | Q13: =SUM(H13:J13) -> 155 | R13: =SUM(K13:M13) -> 195 | S13: =SUM(O13:R13) -> 728
A14: GMC Agoo - Honda | B14: 28 | C14: 25 | D14: 32 | E14: 32 | F14: 32 | G14: 31 | H14: 25 | I14: 25 | J14: 35 | K14: 35 | L14: 35 | M14: 37 | O14: =SUM(B14:D14) -> 85 | P14: =SUM(E14:G14) -> 95 | Q14: =SUM(H14:J14) -> 85 | R14: =SUM(K14:M14) -> 107 | S14: =SUM(O14:R14) -> 372
A15: UEMI Bacnotan - Multi | B15: 25 | C15: 25 | D15: 25 | E15: 32 | F15: 32 | G15: 30 | H15: 25 | I15: 25 | J15: 32 | K15: 33 | L15: 33 | M15: 38 | O15: =SUM(B15:D15) -> 75 | P15: =SUM(E15:G15) -> 94 | Q15: =SUM(H15:J15) -> 82 | R15: =SUM(K15:M15) -> 104 | S15: =SUM(O15:R15) -> 355
A16: UEMI Rosario LU - Multi | B16: 42 | C16: 35 | D16: 43 | E16: 40 | F16: 40 | G16: 35 | H16: 30 | I16: 30 | J16: 35 | K16: 35 | L16: 37 | M16: 40 | O16: =SUM(B16:D16) -> 120 | P16: =SUM(E16+F16+G16) -> 115 | Q16: =SUM(H16+I16+J16) -> 95 | R16: =SUM(K16+L16+M16) -> 112 | S16: =SUM(O16:R16) -> 442
A17: UEMI Agoo - Yamaha | B17: 25 | C17: 25 | D17: 30 | E17: 30 | F17: 30 | G17: 30 | H17: 25 | I17: 25 | J17: 33 | K17: 35 | L17: 35 | M17: 37 | O17: =SUM(B17:D17) -> 80 | P17: =SUM(E17:G17) -> 90 | Q17: =SUM(H17+I17+J17) -> 83 | R17: =SUM(K17+L17+M17) -> 107 | S17: =SUM(O17:R17) -> 360
A18: UEMI Narvacan - Yamaha | B18: 0 | C18: 0 | D18: 0 | E18: 0 | F18: 16 | G18: 25 | H18: 30 | I18: 30 | J18: 36 | K18: 37 | L18: 37 | M18: 39 | O18: =SUM(B18:D18) -> 0 | P18: =SUM(E18:G18) -> 41 | Q18: =SUM(H18:J18) -> 96 | R18: =SUM(K18:M18) -> 113 | S18: =SUM(O18:R18) -> 250
A22: TOTAL | B22: =SUM(B6:B21) -> 568 | C22: =SUM(C6:C21) -> 479 | D22: =SUM(D6:D21) -> 575 | E22: =SUM(E6:E21) -> 557 | F22: =SUM(F6:F21) -> 579 | G22: =SUM(G6:G21) -> 571 | H22: =SUM(H6:H21) -> 464 | I22: =SUM(I6:I21) -> 458 | ... M22: =SUM(M6:M21) -> 668 | O22: =SUM(B22:D22) -> 1622 | P22: =SUM(E22:G22) -> 1707 | Q22: =SUM(H22:J22) -> 1462 | R22: =SUM(K22:M22) -> 1934 | S22: =SUM(O22:R22) -> 6725
A23: AH Goal | B23: =B22 -> 568 | C23: =C22 -> 479 | D23: =D22 -> 575 | E23: =E22 -> 557 | F23: =F22 -> 579 | G23: =G22 -> 571 | H23: =H22 -> 464 | I23: =I22 -> 458 | ... M23: =M22 -> 668 | O23: =SUM(B23:D23) -> 1622 | P23: =SUM(E23:G23) -> 1707 | Q23: =SUM(H23:J23) -> 1462 | R23: =SUM(K23:M23) -> 1934 | S23: =SUM(O23:R23) -> 6725
O24: =O22/S22 -> 0.24118959 | P24: =P22/S22 -> 0.253829 | Q24: =Q22/S22 -> 0.21739777 | R24: =R22/S22 -> 0.28758364 | S24: =SUM(O24:R24) -> 1 | U24: =S24 -> 1
O25: =O23/S23 -> 0.24118959 | P25: =P23/S23 -> 0.253829 | Q25: =Q23/S23 -> 0.21739777 | R25: =R23/S23 -> 0.28758364 | S25: =SUM(O25:R25) -> 1
B28: PREPARED BY:
B31: ARNULFO GUILLEN
B32: GM-MC

Sheet A3
A1: 2019 BRANCH HEAD GOAL: AREA 3
A3: BRANCHES | B3: 1ST QUARTER | E3: 2ND QUARTER | H3: 3RD QUARTER | K3: 4TH QUARTER | O3: GRAND TOTAL
B4: JAN | C4: FEB | D4: MAR | E4: APR | F4: MAY | G4: JUNE | H4: JUL | I4: AUG | J4: SEP | K4: OCT | L4: NOV | M4: DEC | O4: 1Q | P4: 2Q | Q4: 3Q | R4: 4Q | S4: TTL
A6: GMC Dagupan - Honda | B6: 48 | C6: 50 | D6: 50 | E6: 55 | F6: 55 | G6: 50 | H6: 48 | I6: 48 | J6: 48 | K6: 55 | L6: 55 | M6: 55 | O6: =SUM(B6:D6) -> 148 | P6: =SUM(E6:G6) -> 160 | Q6: =SUM(H6:J6) -> 144 | R6: =SUM(K6:M6) -> 165 | S6: =SUM(O6:R6) -> 617
A7: UEMI Dagupan - Yamaha | B7: 50 | C7: 55 | D7: 55 | E7: 60 | F7: 63 | G7: 55 | H7: 50 | I7: 50 | J7: 46 | K7: 65 | L7: 55 | M7: 65 | O7: =SUM(B7:D7) -> 160 | P7: =SUM(E7:G7) -> 178 | Q7: =SUM(H7:J7) -> 146 | R7: =SUM(K7:M7) -> 185 | S7: =SUM(O7:R7) -> 669
A8: UEMI Dagupan - Suzuki | B8: 15 | C8: 16 | D8: 18 | E8: 18 | F8: 18 | G8: 18 | H8: 18 | I8: 18 | J8: 18 | K8: 18 | L8: 18 | M8: 18 | O8: =SUM(B8:D8) -> 49 | P8: =SUM(E8:G8) -> 54 | Q8: =SUM(H8:J8) -> 54 | R8: =SUM(K8:M8) -> 54 | S8: =SUM(O8:R8) -> 211
A9: UEMI Calasiao - Yamaha | B9: 30 | C9: 28 | D9: 33 | E9: 33 | F9: 34 | G9: 33 | H9: 29 | I9: 29 | J9: 30 | K9: 32 | L9: 32 | M9: 35 | O9: =SUM(B9:D9) -> 91 | P9: =SUM(E9:G9) -> 100 | Q9: =SUM(H9:J9) -> 88 | R9: =SUM(K9:M9) -> 99 | S9: =SUM(O9:R9) -> 378
A10: LGK Dagupan - Multi | B10: 15 | C10: 18 | D10: 18 | E10: 19 | F10: 19 | G10: 19 | H10: 18 | I10: 18 | J10: 18 | K10: 18 | L10: 22 | M10: 23 | O10: =SUM(B10:D10) -> 51 | P10: =SUM(E10:G10) -> 57 | Q10: =SUM(H10:J10) -> 54 | R10: =SUM(K10:M10) -> 63 | S10: =SUM(O10:R10) -> 225
A11: UEMI Calasiao - Multi | B11: 22 | C11: 15 | D11: 17 | E11: 17 | F11: 18 | G11: 18 | H11: 15 | I11: 15 | J11: 15 | K11: 17 | L11: 18 | M11: 18 | O11: =SUM(B11:D11) -> 54 | P11: =SUM(E11:G11) -> 53 | Q11: =SUM(H11:J11) -> 45 | R11: =SUM(K11:M11) -> 53 | S11: =SUM(O11:R11) -> 205
A12: MCC Dagupan - Honda | B12: 15 | C12: 15 | D12: 15 | E12: 15 | F12: 15 | G12: 15 | H12: 15 | I12: 15 | J12: 15 | K12: 18 | L12: 20 | M12: 23 | O12: =SUM(B12:D12) -> 45 | P12: =SUM(E12:G12) -> 45 | Q12: =SUM(H12:J12) -> 45 | R12: =SUM(K12:M12) -> 61 | S12: =SUM(O12:R12) -> 196
A13: MCC Calasiao - Honda Wing Shop | B13: 27 | C13: 20 | D13: 20 | E13: 22 | F13: 18 | G13: 22 | H13: 21 | I13: 15 | J13: 21 | K13: 23 | L13: 23 | M13: 23 | O13: =SUM(B13:D13) -> 67 | P13: =SUM(E13:G13) -> 62 | Q13: =SUM(H13:J13) -> 57 | R13: =SUM(K13:M13) -> 69 | S13: =SUM(O13:R13) -> 255
A14: MCC Dagupan - Kawasaki | B14: 15 | C14: 15 | D14: 16 | E14: 17 | F14: 17 | G14: 17 | H14: 17 | I14: 17 | J14: 17 | K14: 17 | L14: 17 | M14: 17 | O14: =SUM(B14:D14) -> 46 | P14: =SUM(E14:G14) -> 51 | Q14: =SUM(H14:J14) -> 51 | R14: =SUM(K14:M14) -> 51 | S14: =SUM(O14:R14) -> 199
A15: UEMI Mangaldan - Multi | B15: 52 | C15: 50 | D15: 60 | E15: 60 | F15: 60 | G15: 60 | H15: 55 | I15: 51 | J15: 51 | K15: 56 | L15: 55 | M15: 65 | N15: 648 | O15: =SUM(B15:D15) -> 162 | P15: =SUM(E15:G15) -> 180 | Q15: =SUM(H15:J15) -> 157 | R15: =SUM(K15:M15) -> 176 | S15: =SUM(O15:R15) -> 675
A16: GMC San Fabian - Honda | B16: 52 | C16: 38 | D16: 49 | E16: 47 | F16: 48 | G16: 45 | H16: 43 | I16: 43 | J16: 43 | K16: 45 | L16: 45 | M16: 55 | N16: 480 | O16: =SUM(B16:D16) -> 139 | P16: =SUM(E16:G16) -> 140 | Q16: =SUM(H16:J16) -> 129 | R16: =SUM(K16:M16) -> 145 | S16: =SUM(O16:R16) -> 553
A17: MCC Sta. Barbara - Honda | B17: 25 | C17: 20 | D17: 25 | E17: 25 | F17: 28 | G17: 27 | H17: 25 | I17: 26 | J17: 26 | K17: 26 | L17: 26 | M17: 26 | O17: =SUM(B17:D17) -> 70 | P17: =SUM(E17:G17) -> 80 | Q17: =SUM(H17:J17) -> 77 | R17: =SUM(K17:M17) -> 78 | S17: =SUM(O17:R17) -> 305
A18: Guanzon Festival | B18: 20 | C18: 0 | D18: 0 | E18: 0 | F18: 0 | G18: 0 | H18: 0 | I18: 0 | J18: 0 | K18: 0 | L18: 0 | M18: 0 | O18: =SUM(B18:D18) -> 20 | P18: =SUM(E18:G18) -> 0 | Q18: =SUM(H18:J18) -> 0 | R18: =SUM(K18:M18) -> 0 | S18: =SUM(O18:R18) -> 20
A19: TOTAL | B19: =SUM(B6:B18) -> 386 | C19: =SUM(C6:C18) -> 340 | D19: =SUM(D6:D18) -> 376 | E19: =SUM(E6:E18) -> 388 | F19: =SUM(F6:F18) -> 393 | G19: =SUM(G6:G18) -> 379 | H19: =SUM(H6:H18) -> 354 | I19: =SUM(I6:I18) -> 345 | ... M19: =SUM(M6:M18) -> 423 | O19: =SUM(O6:O18) -> 1102 | P19: =SUM(P6:P18) -> 1160 | Q19: =SUM(Q6:Q18) -> 1047 | R19: =SUM(R6:R18) -> 1199 | S19: =SUM(S6:S18) -> 4508
A20: AH Goal | B20: 386 | C20: =C19 -> 340 | D20: 370 | E20: 382 | F20: 390 | G20: 378 | H20: =H19 -> 354 | I20: =I19 -> 345 | J20: 345 | K20: =K19 -> 390 | L20: =L19 -> 386 | M20: 420 | O20: =SUM(B20:D20) -> 1096 | P20: =SUM(E20:G20) -> 1150 | Q20: =SUM(H20:J20) -> 1044 | R20: =SUM(K20:M20) -> 1196 | S20: =SUM(O20:R20) -> 4486
O22: =O20/S20 -> 0.24431565 | P22: =P20/S20 -> 0.2563531 | Q22: =Q20/S20 -> 0.23272403 | R22: =R20/S20 -> 0.26660722 | S22: =SUM(O22:R22) -> 1
B23: PREPARED BY:
B26: ARNULFO GUILLEN
B27: GM-MC

Sheet A4
A1: 2019 BRANCH HEAD GOAL: AREA 4
A3: BRANCHES | B3: 1ST QUARTER | E3: 2ND QUARTER | H3: 3RD QUARTER | K3: 4TH QUARTER | O3: GRAND TOTAL
B4: JAN | C4: FEB | D4: MAR | E4: APR | F4: MAY | G4: JUNE | H4: JUL | I4: AUG | J4: SEP | K4: OCT | L4: NOV | M4: DEC | O4: 1Q | P4: 2Q | Q4: 3Q | R4: 4Q | S4: TTL
A6: LGK Urdaneta - Honda | B6: 58 | C6: 50 | D6: 55 | E6: 51 | F6: 56 | G6: 56 | H6: 53 | I6: 53 | J6: 50 | K6: 53 | L6: 54 | M6: 56 | N6: 324 | O6: =SUM(B6:D6) -> 163 | P6: =SUM(E6:G6) -> 163 | Q6: =SUM(H6:J6) -> 156 | R6: =SUM(K6:M6) -> 163 | S6: =SUM(O6:R6) -> 645
A7: LGK Tayug - Multi | B7: 69 | C7: 62 | D7: 65 | E7: 63 | F7: 68 | G7: 68 | H7: 65 | I7: 65 | J7: 65 | K7: 68 | L7: 68 | M7: 70 | N7: 300 | O7: =SUM(B7:D7) -> 196 | P7: =SUM(E7:G7) -> 199 | Q7: =SUM(H7:J7) -> 195 | R7: =SUM(K7:M7) -> 206 | S7: =SUM(O7:R7) -> 796
A8: MCC San Carlos - Honda | B8: 60 | C8: 44 | D8: 48 | E8: 47 | F8: 52 | G8: 51 | H8: 50 | I8: 50 | J8: 45 | K8: 50 | L8: 52 | M8: 53 | N8: 277 | O8: =SUM(B8:D8) -> 152 | P8: =SUM(E8:G8) -> 150 | Q8: =SUM(H8:J8) -> 145 | R8: =SUM(K8:M8) -> 155 | S8: =SUM(O8:R8) -> 602
A9: UEMI Urdaneta - Yamaha | B9: 60 | C9: 61 | D9: 64 | E9: 62 | F9: 64 | G9: 61 | H9: 64 | I9: 62 | J9: 61 | K9: 64 | L9: 65 | M9: 67 | N9: 324 | O9: =SUM(B9:D9) -> 185 | P9: =SUM(E9:G9) -> 187 | Q9: =SUM(H9:J9) -> 187 | R9: =SUM(K9:M9) -> 196 | S9: =SUM(O9:R9) -> 755
A10: LGK Pozorrubio - Honda | B10: 42 | C10: 35 | D10: 40 | E10: 35 | F10: 40 | G10: 35 | H10: 37 | I10: 37 | J10: 37 | K10: 38 | L10: 40 | M10: 40 | N10: 839 | O10: =SUM(B10:D10) -> 117 | P10: =SUM(E10:G10) -> 110 | Q10: =SUM(H10:J10) -> 111 | R10: =SUM(K10:M10) -> 118 | S10: =SUM(O10:R10) -> 456
A11: UEMI Binalonan - Multi | B11: 34 | C11: 32 | D11: 35 | E11: 32 | F11: 36 | G11: 36 | H11: 36 | I11: 36 | J11: 33 | K11: 35 | L11: 35 | M11: 37 | O11: =SUM(B11:D11) -> 101 | P11: =SUM(E11:G11) -> 104 | Q11: =SUM(H11:J11) -> 105 | R11: =SUM(K11:M11) -> 107 | S11: =SUM(O11:R11) -> 417
A12: GMC Bayambang - Honda | B12: 38 | C12: 35 | D12: 38 | E12: 38 | F12: 40 | G12: 38 | H12: 38 | I12: 36 | J12: 36 | K12: 39 | L12: 40 | M12: 41 | N12: 242 | O12: =SUM(B12:D12) -> 111 | P12: =SUM(E12:G12) -> 116 | Q12: =SUM(H12:J12) -> 110 | R12: =SUM(K12:M12) -> 120 | S12: =SUM(O12:R12) -> 457
A13: UEMI Carmen - Multi | B13: 44 | C13: 40 | D13: 40 | E13: 40 | F13: 41 | G13: 41 | H13: 40 | I13: 40 | J13: 40 | K13: 41 | L13: 42 | M13: 43 | N13: 300 | O13: =SUM(B13:D13) -> 124 | P13: =SUM(E13:G13) -> 122 | Q13: =SUM(H13:J13) -> 120 | R13: =SUM(K13:M13) -> 126 | S13: =SUM(O13:R13) -> 492
A14: GMC Manaoag - Honda | B14: 35 | C14: 30 | D14: 33 | E14: 30 | F14: 37 | G14: 35 | H14: 35 | I14: 35 | J14: 33 | K14: 35 | L14: 35 | M14: 35 | N14: 312 | O14: =SUM(B14:D14) -> 98 | P14: =SUM(E14:G14) -> 102 | Q14: =SUM(H14:J14) -> 103 | R14: =SUM(K14:M14) -> 105 | S14: =SUM(O14:R14) -> 408
A15: UEMI Malasiqui - Multi | B15: 39 | C15: 30 | D15: 33 | E15: 30 | F15: 35 | G15: 35 | H15: 35 | I15: 30 | J15: 30 | K15: 35 | L15: 37 | M15: 38 | N15: 288 | O15: =SUM(B15:D15) -> 102 | P15: =SUM(E15:G15) -> 100 | Q15: =SUM(H15:J15) -> 95 | R15: =SUM(K15:M15) -> 110 | S15: =SUM(O15:R15) -> 407
A16: UEMI Tayug - Yamaha | B16: 56 | C16: 56 | D16: 65 | E16: 63 | F16: 65 | G16: 65 | H16: 65 | I16: 65 | J16: 63 | K16: 65 | L16: 66 | M16: 69 | N16: 338 | O16: =SUM(B16:D16) -> 177 | P16: =SUM(E16:G16) -> 193 | Q16: =SUM(H16:J16) -> 193 | R16: =SUM(K16:M16) -> 200 | S16: =SUM(O16:R16) -> 763
A17: UEMI Binalonan - Yamaha | B17: 50 | C17: 48 | D17: 52 | E17: 50 | F17: 54 | G17: 53 | H17: 54 | I17: 54 | J17: 51 | K17: 54 | L17: 54 | M17: 56 | N17: 361 | O17: =SUM(B17:D17) -> 150 | P17: =SUM(E17:G17) -> 157 | Q17: =SUM(H17:J17) -> 159 | R17: =SUM(K17:M17) -> 164 | S17: =SUM(O17:R17) -> 630
A18: UEMI Bayambang - Yamaha | B18: 34 | C18: 32 | D18: 40 | E18: 37 | F18: 40 | G18: 40 | H18: 39 | I18: 38 | J18: 36 | K18: 41 | L18: 42 | M18: 45 | O18: =SUM(B18:D18) -> 106 | P18: =SUM(E18:G18) -> 117 | Q18: =SUM(H18:J18) -> 113 | R18: =SUM(K18:M18) -> 128 | S18: =SUM(O18:R18) -> 464
A19: UEMI Pozorrubio - Yamaha | B19: 40 | C19: 35 | D19: 38 | E19: 35 | F19: 39 | G19: 38 | H19: 35 | I19: 35 | J19: 35 | K19: 40 | L19: 41 | M19: 45 | O19: =SUM(B19:D19) -> 113 | P19: =SUM(E19:G19) -> 112 | Q19: =SUM(H19:J19) -> 105 | R19: =SUM(K19:M19) -> 126 | S19: =SUM(O19:R19) -> 456
A20: UEMI Alcala - Yamaha | B20: 15 | C20: 20 | D20: 30 | E20: 24 | F20: 26 | G20: 28 | H20: 26 | I20: 25 | J20: 25 | K20: 26 | L20: 27 | M20: 28 | O20: =SUM(B20:D20) -> 65 | P20: =SUM(E20:G20) -> 78 | Q20: =SUM(H20:J20) -> 76 | R20: =SUM(K20:M20) -> 81 | S20: =SUM(O20:R20) -> 300
A21: MCC Alcala - Honda | B21: 0 | C21: 0 | D21: 15 | E21: 20 | F21: 24 | G21: 24 | H21: 23 | I21: 23 | J21: 23 | K21: 26 | L21: 30 | M21: 32 | O21: =SUM(B21:D21) -> 15 | P21: =SUM(E21:G21) -> 68 | Q21: =SUM(H21:J21) -> 69 | R21: =SUM(K21:M21) -> 88 | S21: =SUM(O21:R21) -> 240
A22: MCC Asingan - Multi | B22: 0 | C22: 0 | D22: 0 | E22: 0 | F22: 0 | G22: 15 | H22: 18 | I22: 20 | J22: 20 | K22: 25 | L22: 25 | M22: 27 | O22: =SUM(B22:D22) -> 0 | P22: =SUM(E22:G22) -> 15 | Q22: =SUM(H22:J22) -> 58 | R22: =SUM(K22:M22) -> 77 | S22: =SUM(O22:R22) -> 150
A23: MCC Manaoag - Multi | B23: 0 | C23: 0 | D23: 0 | E23: 0 | F23: 20 | G23: 22 | H23: 26 | I23: 26 | J23: 26 | K23: 28 | L23: 30 | M23: 32 | O23: =SUM(B23:D23) -> 0 | P23: =SUM(E23:G23) -> 42 | Q23: =SUM(H23:J23) -> 78 | R23: =SUM(K23:M23) -> 90 | S23: =SUM(O23:R23) -> 210
A24: UEMI Villasis - Yamaha | B24: 0 | C24: 0 | D24: 0 | E24: 0 | F24: 20 | G24: 23 | H24: 25 | I24: 25 | J24: 25 | K24: 30 | L24: 32 | M24: 35 | O24: =SUM(B24:D24) -> 0 | P24: =SUM(E24:G24) -> 43 | Q24: =SUM(H24:J24) -> 75 | R24: =SUM(K24:M24) -> 97 | S24: =SUM(O24:R24) -> 215
A25: UEMI Umingan - Yamaha | B25: 0 | C25: 0 | D25: 0 | E25: 0 | F25: 0 | G25: 0 | H25: 0 | I25: 0 | J25: 0 | K25: 20 | L25: 20 | M25: 20 | O25: =SUM(B25:D25) -> 0 | P25: =SUM(E25:G25) -> 0 | Q25: =SUM(H25:J25) -> 0 | R25: =SUM(K25:M25) -> 60 | S25: =SUM(O25:R25) -> 60
A26: Guanzon Festival | B26: 20 | C26: 0 | D26: 0 | E26: 0 | F26: 0 | G26: 0 | H26: 0 | I26: 0 | J26: 0 | K26: 0 | L26: 0 | M26: 0 | O26: =SUM(B26:M26) -> 20 | P26: =SUM(E26:G26) -> 0 | Q26: =SUM(H26:J26) -> 0 | R26: =SUM(K26:M26) -> 0 | S26: =SUM(O26:R26) -> 20
A27: TOTAL | B27: =SUM(B6:B26) -> 694 | C27: =SUM(C6:C26) -> 610 | D27: =SUM(D6:D26) -> 691 | E27: =SUM(E6:E26) -> 657 | F27: =SUM(F6:F26) -> 757 | G27: =SUM(G6:G26) -> 764 | H27: =SUM(H6:H26) -> 764 | I27: =SUM(I6:I26) -> 755 | ... M27: =SUM(M6:M26) -> 869 | O27: =SUM(B27:D27) -> 1995 | P27: =SUM(E27:G27) -> 2178 | Q27: =SUM(H27:J27) -> 2253 | R27: =SUM(K27:M27) -> 2517 | S27: =SUM(O27:R27) -> 8943
A28: AH Goal | B28: =B27 -> 694 | C28: =C27 -> 610 | D28: =D27 -> 691 | E28: =E27 -> 657 | F28: =F27 -> 757 | G28: =G27 -> 764 | H28: =H27 -> 764 | I28: =I27 -> 755 | ... M28: =M27 -> 869 | O28: =SUM(B28:D28) -> 1995 | P28: =SUM(E28:G28) -> 2178 | Q28: =SUM(H28:J28) -> 2253 | R28: =SUM(K28:M28) -> 2517 | S28: =SUM(O28:R28) -> 8943
O29: =O27/S27 -> 0.2230795 | P29: =P27/S27 -> 0.24354244 | Q29: =Q27/S27 -> 0.25192888 | R29: =R27/S27 -> 0.28144918 | S29: =SUM(O29:R29) -> 1 | U29: =S29 -> 1
O30: =O28/S28 -> 0.2230795 | P30: =P28/S28 -> 0.24354244 | Q30: =Q28/S28 -> 0.25192888 | R30: =R28/S28 -> 0.28144918 | S30: =SUM(O30:R30) -> 1
B31: PREPARED BY:
B34: ARNULFO GUILLEN
B35: GM-MC

Sheet A5
A1: 2019 BRANCH HEAD GOAL: AREA 5
A3: BRANCHES | B3: 1ST QUARTER | E3: 2ND QUARTER | H3: 3RD QUARTER | K3: 4TH QUARTER | O3: GRAND TOTAL
B4: JAN | C4: FEB | D4: MAR | E4: APR | F4: MAY | G4: JUNE | H4: JUL | I4: AUG | J4: SEP | K4: OCT | L4: NOV | M4: DEC | O4: 1Q | P4: 2Q | Q4: 3Q | R4: 4Q | S4: TTL
A6: LGK Alaminos - Honda | B6: 80 | C6: 68 | D6: 77 | E6: 68 | F6: 80 | G6: 65 | H6: 55 | I6: 59 | J6: 63 | K6: 70 | L6: 80 | M6: 100 | O6: =SUM(B6:D6) -> 225 | P6: =SUM(E6:G6) -> 213 | Q6: =SUM(H6:J6) -> 177 | R6: =SUM(K6:M6) -> 250 | S6: =SUM(O6:R6) -> 865
A7: GMC Lingayen - Honda | B7: 60 | C7: 42 | D7: 65 | E7: 59 | F7: 70 | G7: 62 | H7: 57 | I7: 48 | J7: 55 | K7: 62 | L7: 65 | M7: 75 | O7: =SUM(B7:D7) -> 167 | P7: =SUM(E7:G7) -> 191 | Q7: =SUM(H7:J7) -> 160 | R7: =SUM(K7:M7) -> 202 | S7: =SUM(O7:R7) -> 720
A8: GMC Bolinao - Multi | B8: 40 | C8: 38 | D8: 45 | E8: 40 | F8: 48 | G8: 42 | H8: 28 | I8: 30 | J8: 39 | K8: 38 | L8: 41 | M8: 60 | O8: =SUM(B8:D8) -> 123 | P8: =SUM(E8:G8) -> 130 | Q8: =SUM(H8:J8) -> 97 | R8: =SUM(K8:M8) -> 139 | S8: =SUM(O8:R8) -> 489
A9: UEMI Alaminos - Yamaha | B9: 70 | C9: 50 | D9: 67 | E9: 60 | F9: 75 | G9: 65 | H9: 48 | I9: 50 | J9: 50 | K9: 65 | L9: 68 | M9: 74 | O9: =SUM(B9:D9) -> 187 | P9: =SUM(E9:G9) -> 200 | Q9: =SUM(H9:J9) -> 148 | R9: =SUM(K9:M9) -> 207 | S9: =SUM(O9:R9) -> 742
A10: UEMI Lingayen - Yamaha | B10: 63 | C10: 62 | D10: 60 | E10: 55 | F10: 55 | G10: 58 | H10: 55 | I10: 45 | J10: 45 | K10: 56 | L10: 50 | M10: 72 | O10: =SUM(B10:D10) -> 185 | P10: =SUM(E10:G10) -> 168 | Q10: =SUM(H10:J10) -> 145 | R10: =SUM(K10:M10) -> 178 | S10: =SUM(O10:R10) -> 676
A11: UEMI Sta Cruz, Zambales - Multi | B11: 35 | C11: 31 | D11: 38 | E11: 29 | F11: 34 | G11: 35 | H11: 25 | I11: 25 | J11: 28 | K11: 30 | L11: 39 | M11: 50 | O11: =SUM(B11:D11) -> 104 | P11: =SUM(E11:G11) -> 98 | Q11: =SUM(H11:J11) -> 78 | R11: =SUM(K11:M11) -> 119 | S11: =SUM(O11:R11) -> 399
A12: UEMI Iba, Zambales - Multi | B12: 30 | C12: 30 | D12: 31 | E12: 30 | F12: 31 | G12: 33 | H12: 30 | I12: 32 | J12: 30 | K12: 30 | L12: 33 | M12: 37 | O12: =SUM(B12:D12) -> 91 | P12: =SUM(E12:G12) -> 94 | Q12: =SUM(H12:J12) -> 92 | R12: =SUM(K12:M12) -> 100 | S12: =SUM(O12:R12) -> 377
A13: MCC Bolinao - Honda | B13: 55 | C13: 35 | D13: 40 | E13: 35 | F13: 45 | G13: 40 | H13: 30 | I13: 30 | J13: 34 | K13: 35 | L13: 40 | M13: 50 | O13: =SUM(B13:D13) -> 130 | P13: =SUM(E13:G13) -> 120 | Q13: =SUM(H13:J13) -> 94 | R13: =SUM(K13:M13) -> 125 | S13: =SUM(O13:R13) -> 469
A14: UEMI Mangatarem - Yamaha | B14: 30 | C14: 32 | D14: 33 | E14: 28 | F14: 32 | G14: 30 | H14: 25 | I14: 21 | J14: 30 | K14: 32 | L14: 32 | M14: 35 | O14: =SUM(B14:D14) -> 95 | P14: =SUM(E14:G14) -> 90 | Q14: =SUM(H14:J14) -> 76 | R14: =SUM(K14:M14) -> 99 | S14: =SUM(O14:R14) -> 360
A15: MCC Mangatarem - Honda | B15: 35 | C15: 28 | D15: 32 | E15: 25 | F15: 32 | G15: 30 | H15: 27 | I15: 27 | J15: 27 | K15: 30 | L15: 32 | M15: 35 | O15: =SUM(B15:D15) -> 95 | P15: =SUM(E15:G15) -> 87 | Q15: =SUM(H15:J15) -> 81 | R15: =SUM(K15:M15) -> 97 | S15: =SUM(O15:R15) -> 360
A16: UEMI Binmaley - Yamaha | B16: 30 | C16: 29 | D16: 33 | E16: 28 | F16: 30 | G16: 30 | H16: 27 | I16: 26 | J16: 30 | K16: 32 | L16: 32 | M16: 33 | O16: =SUM(B16:D16) -> 92 | P16: =SUM(E16:G16) -> 88 | Q16: =SUM(H16:J16) -> 83 | R16: =SUM(K16:M16) -> 97 | S16: =SUM(O16:R16) -> 360
A17: MCC Bani - Multi | B17: 0 | C17: 0 | D17: 0 | E17: 0 | F17: 15 | G17: 15 | H17: 15 | I17: 15 | J17: 15 | K17: 16 | L17: 18 | M17: 20 | O17: =SUM(B17:D17) -> 0 | P17: =SUM(E17:G17) -> 30 | Q17: =SUM(H17:J17) -> 45 | R17: =SUM(K17:M17) -> 54 | S17: =SUM(O17:R17) -> 129
A18: Guanzon Festival | B18: 20 | C18: 0 | D18: 0 | E18: 0 | F18: 0 | G18: 0 | H18: 0 | I18: 0 | J18: 0 | K18: 0 | L18: 0 | M18: 0 | O18: =SUM(B18:M18) -> 20 | P18: =SUM(E18:G18) -> 0 | Q18: =SUM(H18:J18) -> 0 | R18: =SUM(K18:M18) -> 0 | S18: =SUM(O18:R18) -> 20
A19: TOTAL | B19: =SUM(B6:B18) -> 548 | C19: =SUM(C6:C18) -> 445 | D19: =SUM(D6:D18) -> 521 | E19: =SUM(E6:E18) -> 457 | F19: =SUM(F6:F18) -> 547 | G19: =SUM(G6:G18) -> 505 | H19: =SUM(H6:H18) -> 422 | I19: =SUM(I6:I18) -> 408 | ... M19: =SUM(M6:M18) -> 641 | O19: =SUM(B19:D19) -> 1514 | P19: =SUM(E19:G19) -> 1509 | Q19: =SUM(H19:J19) -> 1276 | R19: =SUM(K19:M19) -> 1667 | S19: =SUM(O19:R19) -> 5966
A20: AH Goal | B20: 548 | C20: 445 | D20: 521 | E20: 457 | F20: 540 | G20: 500 | H20: 422 | I20: 404 | J20: 446 | K20: 496 | L20: 520 | M20: 628 | O20: =SUM(B20:D20) -> 1514 | P20: =SUM(E20:G20) -> 1497 | Q20: =SUM(H20:J20) -> 1272 | R20: =SUM(K20:M20) -> 1644 | S20: =SUM(O20:R20) -> 5927
O21: =O19/S19 -> 0.25377137 | P21: =P19/S19 -> 0.25293329 | Q21: =Q19/S19 -> 0.21387865 | R21: =R19/S19 -> 0.27941669 | S21: =SUM(O21:R21) -> 1 | U21: =S21 -> 1
O22: =O20/S20 -> 0.2554412 | P22: =P20/S20 -> 0.25257297 | Q22: =Q20/S20 -> 0.2146111 | R22: =R20/S20 -> 0.27737473 | S22: =SUM(O22:R22) -> 1
B23: PREPARED BY:
B26: ARNULFO GUILLEN
B27: GM-MC

Sheet A6
A1: 2019 BRANCH HEAD GOAL: AREA 6
A3: BRANCHES | B3: 1ST QUARTER | E3: 2ND QUARTER | H3: 3RD QUARTER | K3: 4TH QUARTER | O3: GRAND TOTAL
B4: JAN | C4: FEB | D4: MAR | E4: APR | F4: MAY | G4: JUNE | H4: JUL | I4: AUG | J4: SEP | K4: OCT | L4: NOV | M4: DEC | O4: 1Q | P4: 2Q | Q4: 3Q | R4: 4Q | S4: TTL
A6: LGK Tarlac - Honda | B6: 45 | C6: 40 | D6: 45 | E6: 40 | F6: 45 | G6: 45 | H6: 40 | I6: 40 | J6: 40 | K6: 45 | L6: 35 | M6: 40 | O6: =SUM(B6:D6) -> 130 | P6: =SUM(E6:G6) -> 130 | Q6: =SUM(H6:J6) -> 120 | R6: =SUM(K6:M6) -> 120 | S6: =SUM(O6:R6) -> 500
A7: UEMI Tarlac - Yamaha | B7: 45 | C7: 40 | D7: 45 | E7: 45 | F7: 45 | G7: 45 | H7: 40 | I7: 35 | J7: 45 | K7: 50 | L7: 45 | M7: 50 | O7: =SUM(B7:D7) -> 130 | P7: =SUM(E7:G7) -> 135 | Q7: =SUM(H7:J7) -> 120 | R7: =SUM(K7:M7) -> 145 | S7: =SUM(O7:R7) -> 530
A8: GMC Sta. Ignacia - Honda | B8: 30 | C8: 25 | D8: 35 | E8: 35 | F8: 35 | G8: 25 | H8: 30 | I8: 25 | J8: 25 | K8: 35 | L8: 48 | M8: 35 | O8: =SUM(B8:D8) -> 90 | P8: =SUM(E8:G8) -> 95 | Q8: =SUM(H8:J8) -> 80 | R8: =SUM(K8:M8) -> 118 | S8: =SUM(O8:R8) -> 383
A9: UEMI Capas - Multi | B9: 35 | C9: 35 | D9: 40 | E9: 40 | F9: 45 | G9: 35 | H9: 30 | I9: 35 | J9: 35 | K9: 35 | L9: 38 | M9: 35 | O9: =SUM(B9:D9) -> 110 | P9: =SUM(E9:G9) -> 120 | Q9: =SUM(H9:J9) -> 100 | R9: =SUM(K9:M9) -> 108 | S9: =SUM(O9:R9) -> 438
A10: GMC Paniqui - Honda | B10: 35 | C10: 30 | D10: 40 | E10: 35 | F10: 40 | G10: 35 | H10: 30 | I10: 25 | J10: 30 | K10: 25 | L10: 30 | M10: 35 | O10: =SUM(B10:D10) -> 105 | P10: =SUM(E10:G10) -> 110 | Q10: =SUM(H10:J10) -> 85 | R10: =SUM(K10:M10) -> 90 | S10: =SUM(O10:R10) -> 390
A11: UEMI Concepcion - Multi | B11: 25 | C11: 30 | D11: 30 | E11: 30 | F11: 30 | G11: 30 | H11: 35 | I11: 25 | J11: 25 | K11: 40 | L11: 25 | M11: 35 | O11: =SUM(B11:D11) -> 85 | P11: =SUM(E11:G11) -> 90 | Q11: =SUM(H11:J11) -> 85 | R11: =SUM(K11:M11) -> 100 | S11: =SUM(O11:R11) -> 360
A12: MCC Camiling - Multi | B12: 35 | C12: 30 | D12: 35 | E12: 35 | F12: 35 | G12: 35 | H12: 30 | I12: 30 | J12: 25 | K12: 35 | L12: 25 | M12: 40 | O12: =SUM(B12:D12) -> 100 | P12: =SUM(E12:G12) -> 105 | Q12: =SUM(H12:J12) -> 85 | R12: =SUM(K12:M12) -> 100 | S12: =SUM(O12:R12) -> 390
A13: UEMI Victoria - Y3S | B13: 25 | C13: 30 | D13: 30 | E13: 30 | F13: 35 | G13: 30 | H13: 30 | I13: 25 | J13: 20 | K13: 30 | L13: 25 | M13: 35 | O13: =SUM(B13:D13) -> 85 | P13: =SUM(E13:G13) -> 95 | Q13: =SUM(H13:J13) -> 75 | R13: =SUM(K13:M13) -> 90 | S13: =SUM(O13:R13) -> 345
A14: MCC Sta. Ignacia - Multi | B14: 0 | C14: 0 | D14: 15 | E14: 18 | F14: 20 | G14: 20 | H14: 20 | I14: 20 | J14: 17 | K14: 20 | L14: 25 | M14: 25 | O14: =SUM(B14:D14) -> 15 | P14: =SUM(E14:G14) -> 58 | Q14: =SUM(H14:J14) -> 57 | R14: =SUM(K14:M14) -> 70 | S14: =SUM(O14:R14) -> 200
A21: TOTAL | B21: =SUM(B6:B20) -> 275 | C21: =SUM(C6:C20) -> 260 | D21: =SUM(D6:D20) -> 315 | E21: =SUM(E6:E20) -> 308 | F21: =SUM(F6:F20) -> 330 | G21: =SUM(G6:G20) -> 300 | H21: =SUM(H6:H20) -> 285 | I21: =SUM(I6:I20) -> 260 | ... M21: =SUM(M6:M20) -> 330 | O21: =SUM(B21:D21) -> 850 | P21: =SUM(E21:G21) -> 938 | Q21: =SUM(H21:J21) -> 807 | R21: =SUM(K21:M21) -> 941 | S21: =SUM(O21:R21) -> 3536
A22: AH Goal | B22: 271 | C22: 257 | D22: 311 | E22: 306 | F22: 326 | G22: 296 | H22: 282 | I22: 256 | J22: 258 | K22: 311 | L22: 296 | M22: 326 | O22: =SUM(B22:D22) -> 839 | P22: =SUM(E22:G22) -> 928 | Q22: =SUM(H22:J22) -> 796 | R22: =SUM(K22:M22) -> 933 | S22: =SUM(O22:R22) -> 3496
O23: =O21/S21 -> 0.24038462 | P23: =P21/S21 -> 0.26527149 | Q23: =Q21/S21 -> 0.22822398 | R23: =R21/S21 -> 0.26611991 | S23: =SUM(O23:R23) -> 1 | U23: =S23 -> 1
O24: =O22/S22 -> 0.23998856 | P24: =P22/S22 -> 0.26544622 | Q24: =Q22/S22 -> 0.22768879 | R24: =R22/S22 -> 0.26687643 | S24: =SUM(O24:R24) -> 1
B25: PREPARED BY:
B28: ARNULFO GUILLEN
B29: GM-MC

Sheet A7
A1: 2019 BRANCH HEAD GOAL: AREA 7
A3: BRANCHES | B3: 1ST QUARTER | E3: 2ND QUARTER | H3: 3RD QUARTER | K3: 4TH QUARTER | O3: GRAND TOTAL
B4: JAN | C4: FEB | D4: MAR | E4: APR | F4: MAY | G4: JUNE | H4: JUL | I4: AUG | J4: SEP | K4: OCT | L4: NOV | M4: DEC | O4: 1Q | P4: 2Q | Q4: 3Q | R4: 4Q | S4: TTL
A6: UEMI Angeles - Multi | B6: 75 | C6: 67 | D6: 70 | E6: 63 | F6: 75 | G6: 65 | H6: 70 | I6: 65 | J6: 65 | K6: 70 | L6: 71 | M6: 80 | N6: 336 | O6: =SUM(B6:D6) -> 212 | P6: =SUM(E6:G6) -> 203 | Q6: =SUM(H6:J6) -> 200 | R6: =SUM(K6:M6) -> 221 | S6: =SUM(O6:R6) -> 836
A7: MCC Dau - Honda | B7: 60 | C7: 52 | D7: 55 | E7: 50 | F7: 55 | G7: 55 | H7: 53 | I7: 55 | J7: 50 | K7: 58 | L7: 53 | M7: 55 | N7: 159 | O7: =SUM(B7:D7) -> 167 | P7: =SUM(E7:G7) -> 160 | Q7: =SUM(H7:J7) -> 158 | R7: =SUM(K7:M7) -> 166 | S7: =SUM(O7:R7) -> 651
A8: UEMI Mabalacat - Yamaha | B8: 63 | C8: 60 | D8: 60 | E8: 57 | F8: 60 | G8: 57 | H8: 55 | I8: 55 | J8: 58 | K8: 58 | L8: 55 | M8: 65 | N8: 552 | O8: =SUM(B8:D8) -> 183 | P8: =SUM(E8:G8) -> 174 | Q8: =SUM(H8:J8) -> 168 | R8: =SUM(K8:M8) -> 178 | S8: =SUM(O8:R8) -> 703
A9: GMC Olongapo - Honda | B9: 40 | C9: 37 | D9: 40 | E9: 38 | F9: 46 | G9: 38 | H9: 38 | I9: 38 | J9: 35 | K9: 42 | L9: 43 | M9: 50 | N9: 611 | O9: =SUM(B9:D9) -> 117 | P9: =SUM(E9:G9) -> 122 | Q9: =SUM(H9:J9) -> 111 | R9: =SUM(K9:M9) -> 135 | S9: =SUM(O9:R9) -> 485
A10: UEMI Balanga - Yamaha | B10: 52 | C10: 45 | D10: 46 | E10: 43 | F10: 60 | G10: 48 | H10: 50 | I10: 52 | J10: 45 | K10: 50 | L10: 50 | M10: 64 | N10: 325 | O10: =SUM(B10:D10) -> 143 | P10: =SUM(E10:G10) -> 151 | Q10: =SUM(H10:J10) -> 147 | R10: =SUM(K10:M10) -> 164 | S10: =SUM(O10:R10) -> 605
A11: UEMI San Fernando - Multi | B11: 38 | C11: 35 | D11: 37 | E11: 36 | F11: 42 | G11: 38 | H11: 36 | I11: 36 | J11: 36 | K11: 38 | L11: 38 | M11: 40 | N11: 240 | O11: =SUM(B11:D11) -> 110 | P11: =SUM(E11:G11) -> 116 | Q11: =SUM(H11:J11) -> 108 | R11: =SUM(K11:M11) -> 116 | S11: =SUM(O11:R11) -> 450
A12: UEMI Lubao - Multi | B12: 27 | C12: 25 | D12: 28 | E12: 26 | F12: 28 | G12: 28 | H12: 27 | I12: 27 | J12: 25 | K12: 28 | L12: 29 | M12: 30 | N12: 370 | O12: =SUM(B12:D12) -> 80 | P12: =SUM(E12:G12) -> 82 | Q12: =SUM(H12:J12) -> 79 | R12: =SUM(K12:M12) -> 87 | S12: =SUM(O12:R12) -> 328
A13: UEMI San Fernando - Yamaha | B13: 35 | C13: 36 | D13: 40 | E13: 38 | F13: 40 | G13: 38 | H13: 38 | I13: 38 | J13: 35 | K13: 39 | L13: 40 | M13: 42 | N13: 263 | O13: =SUM(B13:D13) -> 111 | P13: =SUM(E13:G13) -> 116 | Q13: =SUM(H13:J13) -> 111 | R13: =SUM(K13:M13) -> 121 | S13: =SUM(O13:R13) -> 459
A14: GMC Orani - Honda | B14: 25 | C14: 23 | D14: 25 | E14: 24 | F14: 27 | G14: 30 | H14: 23 | I14: 25 | J14: 23 | K14: 25 | L14: 25 | M14: 26 | N14: 314 | O14: =SUM(B14:D14) -> 73 | P14: =SUM(E14:G14) -> 81 | Q14: =SUM(H14:J14) -> 71 | R14: =SUM(K14:M14) -> 76 | S14: =SUM(O14:R14) -> 301
A15: MCC San Fernando - Multi | B15: 30 | C15: 28 | D15: 30 | E15: 30 | F15: 35 | G15: 30 | H15: 26 | I15: 26 | J15: 25 | K15: 30 | L15: 33 | M15: 35 | O15: =SUM(B15:D15) -> 88 | P15: =SUM(E15:G15) -> 95 | Q15: =SUM(H15:J15) -> 77 | R15: =SUM(K15:M15) -> 98 | S15: =SUM(O15:R15) -> 358
A16: UEMI Subic - Yamaha | B16: 45 | C16: 40 | D16: 40 | E16: 40 | F16: 40 | G16: 40 | H16: 35 | I16: 35 | J16: 35 | K16: 40 | L16: 44 | M16: 50 | O16: =SUM(B16:D16) -> 125 | P16: =SUM(E16:G16) -> 120 | Q16: =SUM(H16:J16) -> 105 | R16: =SUM(K16:M16) -> 134 | S16: =SUM(O16:R16) -> 484
A17: UEMI Floridablanca - Yamaha | B17: 45 | C17: 40 | D17: 40 | E17: 40 | F17: 45 | G17: 40 | H17: 42 | I17: 36 | J17: 42 | K17: 43 | L17: 46 | M17: 47 | O17: =SUM(B17:D17) -> 125 | P17: =SUM(E17:G17) -> 125 | Q17: =SUM(H17:J17) -> 120 | R17: =SUM(K17:M17) -> 136 | S17: =SUM(O17:R17) -> 506
A18: MCC Mabalacat - Multi | B18: 30 | C18: 20 | D18: 25 | E18: 20 | F18: 25 | G18: 25 | H18: 25 | I18: 25 | J18: 25 | K18: 25 | L18: 25 | M18: 30 | O18: =SUM(B18:D18) -> 75 | P18: =SUM(E18:G18) -> 70 | Q18: =SUM(H18:J18) -> 75 | R18: =SUM(K18:M18) -> 80 | S18: =SUM(O18:R18) -> 300
A19: MCC Balanga - Kawasaki | B19: 0 | C19: 0 | D19: 0 | E19: 0 | F19: 0 | G19: 0 | H19: 20 | I19: 20 | J19: 20 | K19: 20 | L19: 20 | M19: 20 | O19: =SUM(B19:D19) -> 0 | P19: =SUM(E19:G19) -> 0 | Q19: =SUM(H19:J19) -> 60 | R19: =SUM(K19:M19) -> 60 | S19: =SUM(O19:R19) -> 120
A20: TOTAL | B20: =SUM(B6:B19) -> 565 | C20: =SUM(C6:C19) -> 508 | D20: =SUM(D6:D19) -> 536 | E20: =SUM(E6:E19) -> 505 | F20: =SUM(F6:F19) -> 578 | G20: =SUM(G6:G19) -> 532 | H20: =SUM(H6:H19) -> 538 | I20: =SUM(I6:I19) -> 533 | ... M20: =SUM(M6:M19) -> 634 | O20: =SUM(B20:D20) -> 1609 | P20: =SUM(E20:G20) -> 1615 | Q20: =SUM(H20:J20) -> 1590 | R20: =SUM(K20:M20) -> 1772 | S20: =SUM(O20:R20) -> 6586
A21: AH Goal | B21: 560 | C21: =C20 -> 508 | D21: =D20 -> 536 | E21: =E20 -> 505 | F21: =F20 -> 578 | G21: 530 | H21: 530 | I21: 525 | J21: 505 | K21: 555 | L21: 565 | M21: 625 | O21: =SUM(B21:D21) -> 1604 | P21: =SUM(E21:G21) -> 1613 | Q21: =SUM(H21:J21) -> 1560 | R21: =SUM(K21:M21) -> 1745 | S21: =SUM(O21:R21) -> 6522
P22: =P20/S20 -> 0.24521713 | Q22: =Q20/S20 -> 0.2414212 | R22: =R20/S20 -> 0.26905557 | S22: =SUM(O22:R22) -> 0.7556939 | U22: =S22 -> 0.7556939
O23: =O21/S21 -> 0.24593683 | P23: =P21/S21 -> 0.24731677 | Q23: =Q21/S21 -> 0.23919043 | R23: =R21/S21 -> 0.26755596 | S23: =SUM(O23:R23) -> 1
B24: PREPARED BY:
B27: ARNULFO GUILLEN
B28: GM-MC

Sheet A8
A1: 2019 BRANCH HEAD GOAL: AREA 8
A3: BRANCHES | B3: 1ST QUARTER | E3: 2ND QUARTER | H3: 3RD QUARTER | K3: 4TH QUARTER | O3: GRAND TOTAL
B4: JAN | C4: FEB | D4: MAR | E4: APR | F4: MAY | G4: JUNE | H4: JUL | I4: AUG | J4: SEP | K4: OCT | L4: NOV | M4: DEC | O4: 1Q | P4: 2Q | Q4: 3Q | R4: 4Q | S4: TTL
A6: UEMI Santiago - Multi | B6: 40 | C6: 35 | D6: 45 | E6: 35 | F6: 50 | G6: 50 | H6: 45 | I6: 45 | J6: 35 | K6: 45 | L6: 48 | M6: 48 | O6: =SUM(B6:D6) -> 120 | P6: =SUM(E6:G6) -> 135 | Q6: =SUM(H6:J6) -> 125 | R6: =SUM(K6:M6) -> 141 | S6: =SUM(O6:R6) -> 521
A7: UEMI Tuguegarao - Multi | B7: 50 | C7: 50 | D7: 55 | E7: 65 | F7: 65 | G7: 60 | H7: 60 | I7: 55 | J7: 55 | K7: 63 | L7: 62 | M7: 65 | O7: =SUM(B7:D7) -> 155 | P7: =SUM(E7:G7) -> 190 | Q7: =SUM(H7:J7) -> 170 | R7: =SUM(K7:M7) -> 190 | S7: =SUM(O7:R7) -> 705
A8: UEMI Tuguegarao - Yamaha | B8: 50 | C8: 50 | D8: 55 | E8: 70 | F8: 70 | G8: 65 | H8: 60 | I8: 55 | J8: 50 | K8: 65 | L8: 68 | M8: 70 | O8: =SUM(B8:D8) -> 155 | P8: =SUM(E8:G8) -> 205 | Q8: =SUM(H8:J8) -> 165 | R8: =SUM(K8:M8) -> 203 | S8: =SUM(O8:R8) -> 728
A9: UEMI Cabanatuan - Multi | B9: 25 | C9: 25 | D9: 28 | E9: 28 | F9: 28 | G9: 30 | H9: 25 | I9: 25 | J9: 25 | K9: 25 | L9: 25 | M9: 25 | O9: =SUM(B9:D9) -> 78 | P9: =SUM(E9:G9) -> 86 | Q9: =SUM(H9:J9) -> 75 | R9: =SUM(K9:M9) -> 75 | S9: =SUM(O9:R9) -> 314
A10: UEMI Solano - Multi | B10: 28 | C10: 25 | D10: 28 | E10: 24 | F10: 28 | G10: 28 | H10: 28 | I10: 26 | J10: 27 | K10: 25 | L10: 28 | M10: 28 | O10: =SUM(B10:D10) -> 81 | P10: =SUM(E10:G10) -> 80 | Q10: =SUM(H10:J10) -> 81 | R10: =SUM(K10:M10) -> 81 | S10: =SUM(O10:R10) -> 323
A11: UEMI Cauayan - Multi | B11: 25 | C11: 23 | D11: 32 | E11: 35 | F11: 40 | G11: 35 | H11: 29 | I11: 30 | J11: 28 | K11: 30 | L11: 28 | M11: 30 | O11: =SUM(B11:D11) -> 80 | P11: =SUM(E11:G11) -> 110 | Q11: =SUM(H11:J11) -> 87 | R11: =SUM(K11:M11) -> 88 | S11: =SUM(O11:R11) -> 365
A12: UEMI Gapan - Multi | B12: 20 | C12: 24 | D12: 25 | E12: 28 | F12: 29 | G12: 29 | H12: 27 | I12: 27 | J12: 27 | K12: 29 | L12: 29 | M12: 29 | O12: =SUM(B12:D12) -> 69 | P12: =SUM(E12:G12) -> 86 | Q12: =SUM(H12:J12) -> 81 | R12: =SUM(K12:M12) -> 87 | S12: =SUM(O12:R12) -> 323
A13: UEMI San Jose - Multi | B13: 18 | C13: 18 | D13: 20 | E13: 20 | F13: 25 | G13: 25 | H13: 22 | I13: 25 | J13: 23 | K13: 23 | L13: 24 | M13: 25 | O13: =SUM(B13:D13) -> 56 | P13: =SUM(E13:G13) -> 70 | Q13: =SUM(H13:J13) -> 70 | R13: =SUM(K13:M13) -> 72 | S13: =SUM(O13:R13) -> 268
A14: UEMI Roxas - Multi | B14: 20 | C14: 23 | D14: 25 | E14: 30 | F14: 30 | G14: 30 | H14: 28 | I14: 28 | J14: 28 | K14: 30 | L14: 30 | M14: 30 | O14: =SUM(B14:D14) -> 68 | P14: =SUM(E14:G14) -> 90 | Q14: =SUM(H14:J14) -> 84 | R14: =SUM(K14:M14) -> 90 | S14: =SUM(O14:R14) -> 332
A15: UEMI Guimba - Multi | B15: 28 | C15: 27 | D15: 28 | E15: 25 | F15: 28 | G15: 28 | H15: 28 | I15: 28 | J15: 28 | K15: 28 | L15: 28 | M15: 28 | O15: =SUM(B15:D15) -> 83 | P15: =SUM(E15:G15) -> 81 | Q15: =SUM(H15:J15) -> 84 | R15: =SUM(K15:M15) -> 84 | S15: =SUM(O15:R15) -> 332
A16: UEMI Tumauini - Multi | B16: 23 | C16: 22 | D16: 23 | E16: 23 | F16: 25 | G16: 25 | H16: 25 | I16: 24 | J16: 25 | K16: 27 | L16: 25 | M16: 27 | O16: =SUM(B16:D16) -> 68 | P16: =SUM(E16:G16) -> 73 | Q16: =SUM(H16:J16) -> 74 | R16: =SUM(K16:M16) -> 79 | S16: =SUM(O16:R16) -> 294
A17: MCC Alicia - Multi | B17: 15 | C17: 18 | D17: 22 | E17: 20 | F17: 18 | G17: 20 | H17: 25 | I17: 25 | J17: 22 | K17: 25 | L17: 23 | M17: 25 | O17: =SUM(B17:D17) -> 55 | P17: =SUM(E17:G17) -> 58 | Q17: =SUM(H17:J17) -> 72 | R17: =SUM(K17:M17) -> 73 | S17: =SUM(O17:R17) -> 258
... A22: MCC Cordon - Multi | B22: 15 | C22: 15 | D22: 18 | E22: 15 | F22: 15 | G22: 15 | H22: 23 | I22: 25 | J22: 22 | K22: 25 | L22: 27 | M22: 25 | O22: =SUM(B22:D22) -> 48 | P22: =SUM(E22:G22) -> 45 | Q22: =SUM(H22:J22) -> 70 | R22: =SUM(K22:M22) -> 77 | S22: =SUM(O22:R22) -> 240
A23: MCC Talavera - Multi | F23: 20 | G23: 20 | H23: 24 | I23: 25 | J23: 25 | K23: 28 | L23: 28 | M23: 30 | O23: =SUM(B23:D23) -> 0 | P23: =SUM(E23:G23) -> 40 | Q23: =SUM(H23:J23) -> 74 | R23: =SUM(K23:M23) -> 86 | S23: =SUM(O23:R23) -> 200
A24: TOTAL | B24: =SUM(B6:B23) -> 433 | C24: =SUM(C6:C23) -> 428 | D24: =SUM(D6:D23) -> 491 | E24: =SUM(E6:E23) -> 505 | F24: =SUM(F6:F23) -> 579 | G24: =SUM(G6:G23) -> 569 | H24: =SUM(H6:H23) -> 546 | I24: =SUM(I6:I23) -> 540 | ... M24: =SUM(M6:M23) -> 596 | O24: =SUM(B24:D24) -> 1352 | P24: =SUM(E24:G24) -> 1653 | Q24: =SUM(H24:J24) -> 1603 | R24: =SUM(K24:M24) -> 1752 | S24: =SUM(O24:R24) -> 6360
A25: AH Goal | B25: 431 | C25: 428 | D25: 485 | E25: 505 | F25: 572 | G25: 560 | H25: 546 | I25: 540 | J25: 517 | K25: 566 | L25: 576 | M25: 586 | O25: =SUM(B25:D25) -> 1344 | P25: =SUM(E25:G25) -> 1637 | Q25: =SUM(H25:J25) -> 1603 | R25: =SUM(K25:M25) -> 1728 | S25: =SUM(O25:R25) -> 6312
O26: =O24/S24 -> 0.21257862 | P26: =P24/S24 -> 0.25990566 | Q26: =Q24/S24 -> 0.25204403 | R26: =R24/S24 -> 0.2754717 | S26: =SUM(O26:R26) -> 1 | U26: =S26 -> 1
O27: =O25/S25 -> 0.21292776 | P27: =P25/S25 -> 0.25934728 | Q27: =Q25/S25 -> 0.25396071 | R27: =R25/S25 -> 0.27376426 | S27: =SUM(O27:R27) -> 1
B28: PREPARED BY:
B31: ARNULFO GUILLEN
B32: GM-MC

Sheet A9
A1: 2019 BRANCH HEAD GOAL: AREA 9
A3: BRANCHES | B3: 1ST QUARTER | E3: 2ND QUARTER | H3: 3RD QUARTER | K3: 4TH QUARTER | O3: GRAND TOTAL
B4: JAN | C4: FEB | D4: MAR | E4: APR | F4: MAY | G4: JUNE | H4: JUL | I4: AUG | J4: SEP | K4: OCT | L4: NOV | M4: DEC | O4: 1Q | P4: 2Q | Q4: 3Q | R4: 4Q | S4: TTL
A6: UEMI Cainta - Yamaha | B6: 100 | C6: 92 | D6: 100 | E6: 92 | F6: 100 | G6: 96 | H6: 104 | I6: 98 | J6: 98 | K6: 104 | L6: 90 | M6: 90 | O6: =SUM(B6:D6) -> 292 | P6: =SUM(E6:G6) -> 288 | Q6: =SUM(H6:J6) -> 300 | R6: =SUM(K6:M6) -> 284 | S6: =SUM(O6:R6) -> 1164
A7: GMC E.Rodriguez - Honda | B7: 50 | C7: 46 | D7: 50 | E7: 46 | F7: 50 | G7: 48 | H7: 52 | I7: 50 | J7: 48 | K7: 52 | L7: 46 | M7: 45 | O7: =SUM(B7:D7) -> 146 | P7: =SUM(E7:G7) -> 144 | Q7: =SUM(H7:J7) -> 150 | R7: =SUM(K7:M7) -> 143 | S7: =SUM(O7:R7) -> 583
A8: UEMI Roosevelt - Suzuki | B8: 54 | C8: 50 | D8: 54 | E8: 50 | F8: 54 | G8: 52 | H8: 56 | I8: 54 | J8: 54 | K8: 56 | L8: 50 | M8: 50 | O8: =SUM(B8:D8) -> 158 | P8: =SUM(E8:G8) -> 156 | Q8: =SUM(H8:J8) -> 164 | R8: =SUM(K8:M8) -> 156 | S8: =SUM(O8:R8) -> 634
A9: UEMI Valenzuela - Multi | B9: 42 | C9: 39 | D9: 42 | E9: 39 | F9: 42 | G9: 40 | H9: 43 | I9: 42 | J9: 42 | K9: 44 | L9: 40 | M9: 40 | O9: =SUM(B9:D9) -> 123 | P9: =SUM(E9:G9) -> 121 | Q9: =SUM(H9:J9) -> 127 | R9: =SUM(K9:M9) -> 124 | S9: =SUM(O9:R9) -> 495
A10: MCC Marilao - Honda | B10: 42 | C10: 37 | D10: 41 | E10: 36 | F10: 41 | G10: 39 | H10: 42 | I10: 40 | J10: 40 | K10: 42 | L10: 37 | M10: 36 | O10: =SUM(B10:D10) -> 120 | P10: =SUM(E10:G10) -> 116 | Q10: =SUM(H10:J10) -> 122 | R10: =SUM(K10:M10) -> 115 | S10: =SUM(O10:R10) -> 473
A11: UEMI Balagtas - Yamaha | B11: 50 | C11: 46 | D11: 50 | E11: 46 | F11: 50 | G11: 48 | H11: 50 | I11: 50 | J11: 48 | K11: 52 | L11: 46 | M11: 44 | O11: =SUM(B11:D11) -> 146 | P11: =SUM(E11:G11) -> 144 | Q11: =SUM(H11:J11) -> 148 | R11: =SUM(K11:M11) -> 142 | S11: =SUM(O11:R11) -> 580
A12: MCC Caloocan - Honda | B12: 36 | C12: 33 | D12: 36 | E12: 33 | F12: 36 | G12: 35 | H12: 37 | I12: 35 | J12: 36 | K12: 37 | L12: 33 | M12: 33 | O12: =SUM(B12:D12) -> 105 | P12: =SUM(E12:G12) -> 104 | Q12: =SUM(H12:J12) -> 108 | R12: =SUM(K12:M12) -> 103 | S12: =SUM(O12:R12) -> 420
A13: UEMI Baliuag - Multi | B13: 28 | C13: 26 | D13: 29 | E13: 27 | F13: 29 | G13: 28 | H13: 29 | I13: 29 | J13: 28 | K13: 30 | L13: 27 | M13: 26 | O13: =SUM(B13:D13) -> 83 | P13: =SUM(E13:G13) -> 84 | Q13: =SUM(H13:J13) -> 86 | R13: =SUM(K13:M13) -> 83 | S13: =SUM(O13:R13) -> 336
A14: UEMI Taytay - Suzuki | B14: 36 | C14: 34 | D14: 36 | E14: 34 | F14: 36 | G14: 35 | H14: 38 | I14: 35 | J14: 36 | K14: 38 | L14: 34 | M14: 33 | O14: =SUM(B14:D14) -> 106 | P14: =SUM(E14:G14) -> 105 | Q14: =SUM(H14:J14) -> 109 | R14: =SUM(K14:M14) -> 105 | S14: =SUM(O14:R14) -> 425
A15: UEMI Malolos - Multi | B15: 26 | C15: 24 | D15: 26 | E15: 24 | F15: 26 | G15: 24 | H15: 27 | I15: 26 | J15: 26 | K15: 28 | L15: 25 | M15: 26 | O15: =SUM(B15:D15) -> 76 | P15: =SUM(E15:G15) -> 74 | Q15: =SUM(H15:J15) -> 79 | R15: =SUM(K15:M15) -> 79 | S15: =SUM(O15:R15) -> 308
A16: MCC Roosevelt - Honda | B16: 36 | C16: 33 | D16: 36 | E16: 33 | F16: 36 | G16: 35 | H16: 37 | I16: 36 | J16: 35 | K16: 37 | L16: 33 | M16: 33 | O16: =SUM(B16:D16) -> 105 | P16: =SUM(E16:G16) -> 104 | Q16: =SUM(H16:J16) -> 108 | R16: =SUM(K16:M16) -> 103 | S16: =SUM(O16:R16) -> 420
A17: MCC Tondo - Honda | B17: 0 | C17: 0 | D17: 0 | E17: 0 | F17: 0 | G17: 0 | H17: 15 | I17: 20 | J17: 25 | K17: 25 | L17: 25 | M17: 30 | O17: =SUM(B17:D17) -> 0 | P17: =SUM(E17:G17) -> 0 | Q17: =SUM(H17:J17) -> 60 | R17: =SUM(K17:M17) -> 80 | S17: =SUM(O17:R17) -> 140
A20: TOTAL | B20: =SUM(B6:B19) -> 500 | C20: =SUM(C6:C19) -> 460 | D20: =SUM(D6:D19) -> 500 | E20: =SUM(E6:E19) -> 460 | F20: =SUM(F6:F19) -> 500 | G20: =SUM(G6:G19) -> 480 | H20: =SUM(H6:H19) -> 530 | I20: =SUM(I6:I19) -> 515 | ... M20: =SUM(M6:M19) -> 486 | O20: =SUM(B20:D20) -> 1460 | P20: =SUM(E20:G20) -> 1440 | Q20: =SUM(H20:J20) -> 1561 | R20: =SUM(K20:M20) -> 1517 | S20: =SUM(O20:R20) -> 5978
A21: AH Goal | B21: =B20 -> 500 | C21: =C20 -> 460 | D21: =D20 -> 500 | E21: =E20 -> 460 | F21: =F20 -> 500 | G21: =G20 -> 480 | H21: =H20 -> 530 | I21: =I20 -> 515 | ... M21: =M20 -> 486 | O21: =SUM(B21:D21) -> 1460 | P21: =SUM(E21:G21) -> 1440 | Q21: =SUM(H21:J21) -> 1561 | R21: =SUM(K21:M21) -> 1517 | S21: =SUM(O21:R21) -> 5978
O22: =O20/S20 -> 0.24422884 | P22: =P20/S20 -> 0.24088324 | Q22: =Q20/S20 -> 0.26112412 | R22: =R20/S20 -> 0.2537638 | S22: =SUM(O22:R22) -> 1 | U22: =S22 -> 1
O23: =O21/S21 -> 0.24422884 | P23: =P21/S21 -> 0.24088324 | Q23: =Q21/S21 -> 0.26112412 | R23: =R21/S21 -> 0.2537638 | S23: =SUM(O23:R23) -> 1
B24: PREPARED BY:
B27: ARNULFO GUILLEN
B28: GM-MC

Sheet A10
A1: 2019 BRANCH HEAD GOAL: AREA 10
A3: BRANCHES | B3: 1ST QUARTER | E3: 2ND QUARTER | H3: 3RD QUARTER | K3: 4TH QUARTER | O3: GRAND TOTAL
B4: JAN | C4: FEB | D4: MAR | E4: APR | F4: MAY | G4: JUNE | H4: JUL | I4: AUG | J4: SEP | K4: OCT | L4: NOV | M4: DEC | O4: 1Q | P4: 2Q | Q4: 3Q | R4: 4Q | S4: TTL
A6: UEMI Naic - Y3S | B6: 65 | C6: 60 | D6: 65 | E6: 60 | F6: 65 | G6: 65 | H6: 65 | I6: 65 | J6: 60 | K6: 65 | L6: 65 | M6: 70 | O6: =SUM(B6:D6) -> 190 | P6: =SUM(E6:G6) -> 190 | Q6: =SUM(H6:J6) -> 190 | R6: =SUM(K6:M6) -> 200 | S6: =SUM(O6:R6) -> 770
A7: UEMI Calamba - Multi | B7: 35 | C7: 25 | D7: 34 | E7: 28 | F7: 34 | G7: 32 | H7: 32 | I7: 30 | J7: 30 | K7: 35 | L7: 37 | M7: 38 | O7: =SUM(B7:D7) -> 94 | P7: =SUM(E7:G7) -> 94 | Q7: =SUM(H7:J7) -> 92 | R7: =SUM(K7:M7) -> 110 | S7: =SUM(O7:R7) -> 390
A8: UEMI Makati - Multi | B8: 35 | C8: 28 | D8: 35 | E8: 30 | F8: 32 | G8: 33 | H8: 30 | I8: 30 | J8: 30 | K8: 35 | L8: 35 | M8: 35 | O8: =SUM(B8:D8) -> 98 | P8: =SUM(E8:G8) -> 95 | Q8: =SUM(H8:J8) -> 90 | R8: =SUM(K8:M8) -> 105 | S8: =SUM(O8:R8) -> 388
A9: UEMI Imus - Multi | B9: 35 | C9: 28 | D9: 35 | E9: 30 | F9: 35 | G9: 35 | H9: 30 | I9: 30 | J9: 30 | K9: 34 | L9: 38 | M9: 40 | O9: =SUM(B9:D9) -> 98 | P9: =SUM(E9:G9) -> 100 | Q9: =SUM(H9:J9) -> 90 | R9: =SUM(K9:M9) -> 112 | S9: =SUM(O9:R9) -> 400
A10: UEMI Alabang - Multi | B10: 40 | C10: 35 | D10: 40 | E10: 35 | F10: 40 | G10: 40 | H10: 40 | I10: 40 | J10: 35 | K10: 45 | L10: 45 | M10: 45 | O10: =SUM(B10:D10) -> 115 | P10: =SUM(E10:G10) -> 115 | Q10: =SUM(H10:J10) -> 115 | R10: =SUM(K10:M10) -> 135 | S10: =SUM(O10:R10) -> 480
A11: UEMI Carmona - Multi | B11: 30 | C11: 28 | D11: 34 | E11: 30 | F11: 34 | G11: 34 | H11: 35 | I11: 30 | J11: 30 | K11: 32 | L11: 34 | M11: 36 | O11: =SUM(B11:D11) -> 92 | P11: =SUM(E11:G11) -> 98 | Q11: =SUM(H11:J11) -> 95 | R11: =SUM(K11:M11) -> 102 | S11: =SUM(O11:R11) -> 387
A12: UEMI Sta Cruz - Multi | B12: 25 | C12: 20 | D12: 32 | E12: 22 | F12: 30 | G12: 30 | H12: 28 | I12: 25 | J12: 25 | K12: 28 | L12: 31 | M12: 33 | O12: =SUM(B12:D12) -> 77 | P12: =SUM(E12:G12) -> 82 | Q12: =SUM(H12:J12) -> 78 | R12: =SUM(K12:M12) -> 92 | S12: =SUM(O12:R12) -> 329
A13: UEMI Sta. Rosa - Multi | B13: 25 | C13: 20 | D13: 25 | E13: 20 | F13: 30 | G13: 25 | H13: 25 | I13: 21 | J13: 20 | K13: 25 | L13: 25 | M13: 30 | O13: =SUM(B13:D13) -> 70 | P13: =SUM(E13:G13) -> 75 | Q13: =SUM(H13:J13) -> 66 | R13: =SUM(K13:M13) -> 80 | S13: =SUM(O13:R13) -> 291
A14: MCC Naic - Multi | B14: 34 | C14: 30 | D14: 30 | E14: 34 | F14: 35 | G14: 34 | H14: 30 | I14: 35 | J14: 35 | K14: 34 | L14: 34 | M14: 35 | O14: =SUM(B14:D14) -> 94 | P14: =SUM(E14:G14) -> 103 | Q14: =SUM(H14:J14) -> 100 | R14: =SUM(K14:M14) -> 103 | S14: =SUM(O14:R14) -> 400
A15: UEMI San Pablo - Y3S | B15: 22 | C15: 20 | D15: 21 | E15: 22 | F15: 28 | G15: 28 | H15: 30 | I15: 25 | J15: 25 | K15: 30 | L15: 32 | M15: 32 | O15: =SUM(B15:D15) -> 63 | P15: =SUM(E15:G15) -> 78 | Q15: =SUM(H15:J15) -> 80 | R15: =SUM(K15:M15) -> 94 | S15: =SUM(O15:R15) -> 315
A19: TOTAL | B19: =SUM(B6:B18) -> 346 | C19: =SUM(C6:C18) -> 294 | D19: =SUM(D6:D18) -> 351 | E19: =SUM(E6:E18) -> 311 | F19: =SUM(F6:F18) -> 363 | G19: =SUM(G6:G18) -> 356 | H19: =SUM(H6:H18) -> 345 | I19: =SUM(I6:I18) -> 331 | ... M19: =SUM(M6:M18) -> 394 | O19: =SUM(B19:D19) -> 991 | P19: =SUM(E19:G19) -> 1030 | Q19: =SUM(H19:J19) -> 996 | R19: =SUM(K19:M19) -> 1133 | S19: =SUM(O19:R19) -> 4150
A20: AH Goal | B20: 310 | C20: 310 | D20: 340 | E20: 300 | F20: 350 | G20: 330 | H20: 339 | I20: 320 | J20: 330 | K20: 340 | L20: 330 | M20: 360 | O20: =SUM(B20:D20) -> 960 | P20: =SUM(E20:G20) -> 980 | Q20: =SUM(H20:J20) -> 989 | R20: =SUM(K20:M20) -> 1030 | S20: =SUM(O20:R20) -> 3959
O21: =O19/S19 -> 0.23879518 | P21: =P19/S19 -> 0.24819277 | Q21: =Q19/S19 -> 0.24 | R21: =R19/S19 -> 0.27301205 | S21: =SUM(O21:R21) -> 1 | U21: =S21 -> 1
O22: =O20/S20 -> 0.24248548 | P22: =P20/S20 -> 0.24753726 | Q22: =Q20/S20 -> 0.24981056 | R22: =R20/S20 -> 0.26016671 | S22: =SUM(O22:R22) -> 1
B23: PREPARED BY:
B26: ARNULFO GUILLEN
B27: GM-MC

Sheet A11
A1: 2019 BRANCH HEAD GOAL: AREA 11
A3: BRANCHES | B3: 1ST QUARTER | E3: 2ND QUARTER | H3: 3RD QUARTER | K3: 4TH QUARTER | O3: GRAND TOTAL
B4: JAN | C4: FEB | D4: MAR | E4: APR | F4: MAY | G4: JUNE | H4: JUL | I4: AUG | J4: SEP | K4: OCT | L4: NOV | M4: DEC | O4: 1Q | P4: 2Q | Q4: 3Q | R4: 4Q | S4: TTL
A6: UEMI Brookespoint - Multi | B6: 15 | C6: 15 | D6: 18 | E6: 17 | F6: 16 | G6: 16 | H6: 16 | I6: 16 | J6: 16 | K6: 18 | L6: 20 | M6: 23 | O6: =SUM(B6:D6) -> 48 | P6: =SUM(E6:G6) -> 49 | Q6: =SUM(H6:J6) -> 48 | R6: =SUM(K6:M6) -> 61 | S6: =SUM(O6:R6) -> 206
A7: UEMI Palawan - Yamaha | B7: 16 | C7: 15 | D7: 20 | E7: 18 | F7: 20 | G7: 18 | H7: 18 | I7: 20 | J7: 18 | K7: 20 | L7: 21 | M7: 22 | O7: =SUM(B7:D7) -> 51 | P7: =SUM(E7:G7) -> 56 | Q7: =SUM(H7:J7) -> 56 | R7: =SUM(K7:M7) -> 63 | S7: =SUM(O7:R7) -> 226
A8: MCC Roxas Palawan - MB | B8: 15 | C8: 15 | D8: 15 | E8: 15 | F8: 16 | G8: 17 | H8: 15 | I8: 15 | J8: 15 | K8: 17 | L8: 18 | M8: 20 | O8: =SUM(B8:D8) -> 45 | P8: =SUM(E8:G8) -> 48 | Q8: =SUM(H8:J8) -> 45 | R8: =SUM(K8:M8) -> 55 | S8: =SUM(O8:R8) -> 193
A9: Puerto Princesa - MB
A18: TOTAL | B18: =SUM(B6:B17) -> 46 | C18: =SUM(C6:C17) -> 45 | D18: =SUM(D6:D17) -> 53 | E18: =SUM(E6:E17) -> 50 | F18: =SUM(F6:F17) -> 52 | G18: =SUM(G6:G17) -> 51 | H18: =SUM(H6:H17) -> 49 | I18: =SUM(I6:I17) -> 51 | ... M18: =SUM(M6:M17) -> 65 | O18: =SUM(B18:D18) -> 144 | P18: =SUM(E18:G18) -> 153 | Q18: =SUM(H18:J18) -> 149 | R18: =SUM(K18:M18) -> 179 | S18: =SUM(O18:R18) -> 625
A19: AH Goal | B19: 46 | C19: 46 | D19: 52 | E19: 48 | F19: 50 | G19: 49 | H19: 48 | I19: 49 | J19: 48 | K19: 54 | L19: 57 | M19: 64 | O19: =SUM(B19:D19) -> 144 | P19: =SUM(E19:G19) -> 147 | Q19: =SUM(H19:J19) -> 145 | R19: =SUM(K19:M19) -> 175 | S19: =SUM(O19:R19) -> 611
B20: 18 | C20: 15 | D20: 16 | E20: 18 | F20: 18 | G20: 16 | H20: 16 | I20: 15 | J20: 15 | K20: 18 | L20: 20 | M20: 24 | O20: =O18/S18 -> 0.2304 | P20: =P18/S18 -> 0.2448 | Q20: =Q18/S18 -> 0.2384 | R20: =R18/S18 -> 0.2864 | S20: =SUM(O20:R20) -> 1 | U20: =S20 -> 1
B21: 50 | C21: 45 | D21: 58 | E21: 60 | F21: 61 | G21: 61 | H21: 60 | I21: 57 | J21: 58 | K21: 64 | L21: 67 | M21: 77 | O21: =O19/S19 -> 0.23567921 | P21: =P19/S19 -> 0.2405892 | Q21: =Q19/S19 -> 0.23731588 | R21: =R19/S19 -> 0.28641571 | S21: =SUM(O21:R21) -> 1
B22: PREPARED BY:
B25: ARNULFO GUILLEN
B26: GM-MC

Sheet A12
A1: 2019 BRANCH HEAD GOAL: AREA 12
A3: BRANCHES | B3: 1ST QUARTER | E3: 2ND QUARTER | H3: 3RD QUARTER | K3: 4TH QUARTER | O3: GRAND TOTAL
B4: JAN | C4: FEB | D4: MAR | E4: APR | F4: MAY | G4: JUNE | H4: JUL | I4: AUG | J4: SEP | K4: OCT | L4: NOV | M4: DEC | O4: 1Q | P4: 2Q | Q4: 3Q | R4: 4Q | S4: TTL
