Workbook

Sheet pending federico
A1: sBranchNm | B1: JO Status | C1: Status | D1: sTransNox | E1: dTransact | F1: sBranchCd | G1: sRequestX | H1: sDiagnose | I1: sJOTypexx | J1: sCategory | K1: cServerPC | L1: sProblemx | M1: sRemarksx | N1: sRqstdIDx | O1: sSupprtBy | P1: dPostedxx | Q1: ACTUAL STATUS | R1: ACTUAL STATUS no formula | S1: STATUS2 | T1: sModified | U1: Encoder | V1: dModified
A2: UEMI San Nicolas - Yamaha | B2: REPAIRED | C2: OPEN | D2: M00120000472 | E2: 44165 | F2: M144 | G2: printer sharing | I2: SUPPORT ASSISTANCE(ACCESS, CALLS..) | J2: PRINTER | K2: 0 | N2: M00119000532 | P2: 44165 | Q2: SUPPORTED WITHIN 2DAYS | R2: SUPPORTED WITHIN 2DAYS | S2: 0 | T2: M001170038 | U2: Macarling, Federico Jr Romano | V2: 44165.42
A3: Guan Kai Office | B3: REPAIRED | C3: OPEN | D3: M00120000471 | E3: 44165 | F3: GK01 | G3: virus infected PC of CSS-Elle Rosal | I3: REPAIR | J3: SYSTEM UNIT | K3: 0 | N3: M00119000532 | P3: 44165 | Q3: SUPPORTED WITHIN 2DAYS | R3: SUPPORTED WITHIN 2DAYS | S3: 0 | T3: M001170038 | U3: Macarling, Federico Jr Romano | V3: 44165.414
A4: Guanzon Central Office | B4: REPAIRED | C4: OPEN | D4: M00120000470 | E4: 44165 | F4: GCO1 | G4: reformat Sir Richard laptop | I4: REPAIR | J4: TECHNICAL SUPPORT | K4: 0 | P4: 44165 | Q4: SUPPORTED WITHIN 2DAYS | R4: SUPPORTED WITHIN 2DAYS | S4: 0 | T4: M001170038 | U4: Macarling, Federico Jr Romano | V4: 44165.412
A5: Mobitek Magic Urdaneta | B5: REPAIRED | C5: OPEN | D5: M00120000469 | E5: 44165 | F5: C006 | G5: PLDT - no dial tone no internet. for temporary issue pocket wifi | I5: SUPPORT ASSISTANCE(ACCESS, CALLS..) | J5: ISP CONCERN | K5: 0 | P5: 44165 | Q5: SUPPORTED WITHIN 2DAYS | R5: SUPPORTED WITHIN 2DAYS | S5: 0 | T5: M001170038 | U5: Macarling, Federico Jr Romano | V5: 44165.405
A6: Guanzon Corporate Center | B6: REPAIRED | C6: OPEN | D6: M00120000468 | E6: 44165 | F6: GCC1 | G6: reset printer of TAX - Epson L120 | I6: REPAIR | J6: PRINTER | K6: 0 | N6: M00111006212 | P6: 44165 | Q6: SUPPORTED WITHIN 2DAYS | R6: SUPPORTED WITHIN 2DAYS | S6: 0 | T6: M001170038 | U6: Macarling, Federico Jr Romano | V6: 44165.375
A7: Mobitek Vigan | B7: REPAIRED | C7: OPEN | D7: M00120000458 | E7: 44163 | F7: C015 | G7: Assist Sir George Esperida about Slow performace of his LAPTOP | I7: SUPPORT ASSISTANCE(ACCESS, CALLS..) | J7: TECHNICAL SUPPORT | K7: 0 | N7: M01606001405 | P7: 44163 | Q7: SUPPORTED WITHIN 2DAYS | R7: SUPPORTED WITHIN 2DAYS | S7: 0 | T7: M001170038 | U7: Macarling, Federico Jr Romano | V7: 44163.486
A8: Guan Kai Office | B8: REPAIRED | C8: OPEN | D8: M00120000422 | E8: 44161 | F8: GK01 | G8: pick up laptop charger of Sir Arnold Guillen - GMA Office | I8: Others | J8: OTHER PERIPHERAL DEVICES | K8: 0 | N8: M00109011793 | P8: 44161 | Q8: SUPPORTED WITHIN 2DAYS | R8: SUPPORTED WITHIN 2DAYS | S8: 0 | T8: M001170038 | U8: Macarling, Federico Jr Romano | V8: 44161.59
A9: Guanzon Corporate Center | B9: REPAIRED | C9: OPEN | D9: M00120000420 | E9: 44161 | F9: GCC1 | G9: records - request scanner only | I9: Others | J9: OTHER PERIPHERAL DEVICES | K9: 0 | N9: M00110012546 | P9: 44161 | Q9: SUPPORTED WITHIN 2DAYS | R9: SUPPORTED WITHIN 2DAYS | S9: 0 | T9: M001170038 | U9: Macarling, Federico Jr Romano | V9: 44161.436
A10: Samsung - SM Telabastagan | B10: REPAIRED | C10: OPEN | D10: M00120000411 | E10: 44159 | F10: C073 | G10: All camera - naglolose pag nagagalaw ng branch., need to relocate position of DVR. FOR VISIT | I10: REPAIR | J10: CCTV | K10: 0 | P10: 44159 | Q10: SUPPORTED WITHIN 2DAYS | R10: SUPPORTED WITHIN 2DAYS | S10: 0 | T10: M001170038 | U10: Macarling, Federico Jr Romano | V10: 44159.693
A11: Guan Kai Office | B11: REPAIRED | C11: OPEN | D11: M00120000410 | E11: 44159 | F11: GK01 | G11: GK Line 2 - no dial tone - follow up thru email | I11: REPAIR | J11: ISP CONCERN | K11: 0 | P11: 44159 | Q11: SUPPORTED WITHIN 2DAYS | R11: SUPPORTED WITHIN 2DAYS | S11: 0 | T11: M001170038 | U11: Macarling, Federico Jr Romano | V11: 44159.692
A12: LGK Pozorrubio - Honda | B12: REPAIRED | C12: OPEN | D12: M00120000404 | E12: 44156 | F12: M038 | G12: Asset transfer - repaired server PC | I12: INSTALLATION & CONFIGURATION | J12: Others | K12: 0 | N12: M00109019180 | P12: 44156 | Q12: SUPPORTED WITHIN 2DAYS | R12: SUPPORTED WITHIN 2DAYS | S12: 0 | T12: M001170038 | U12: Macarling, Federico Jr Romano | V12: 44156.69
A13: Guanzon Corporate Center | B13: REPAIRED | C13: OPEN | D13: M00120000403 | E13: 44156 | F13: GCC1 | G13: release Epson L120 - for Anolid Shipping (Asset transfer) | I13: Others | J13: PRINTER | K13: 0 | N13: M00109019180 | P13: 44156 | Q13: SUPPORTED WITHIN 2DAYS | R13: SUPPORTED WITHIN 2DAYS | S13: 0 | T13: M001170038 | U13: Macarling, Federico Jr Romano | V13: 44156.69
A14: Guanzon Central Office | B14: REPAIRED | C14: OPEN | D14: M00120000398 | E14: 44156 | F14: GCO1 | G14: laptop of engineer amy. Install autocad, and other engineering apps | I14: INSTALLATION & CONFIGURATION | J14: OTHER PERIPHERAL DEVICES | K14: 0 | N14: M00110018534 | P14: 44156 | Q14: SUPPORTED WITHIN 2DAYS | R14: SUPPORTED WITHIN 2DAYS | S14: 0 | T14: M001170038 | U14: Macarling, Federico Jr Romano | V14: 44156.543
A15: Guan Kai Office | B15: REPAIRED | C15: OPEN | D15: M00120000397 | E15: 44155 | F15: GK01 | G15: Antenna at GK pointing Suzuki Dagupan - can't access need to check | I15: Others | J15: OTHER PERIPHERAL DEVICES | K15: 0 | N15: M00105000801 | P15: 44156 | Q15: SUPPORTED WITHIN 2DAYS | R15: SUPPORTED WITHIN 2DAYS | S15: 0 | T15: M001170038 | U15: Macarling, Federico Jr Romano | V15: 44156.542
A16: Guanzon Central Office | B16: REPAIRED | C16: OPEN | D16: M00120000396 | E16: 44155 | F16: GCO1 | G16: Video card of Boss Jude Lo. for checking | I16: Others | J16: OTHER PERIPHERAL DEVICES | K16: 0 | N16: M00105000801 | P16: 44156 | Q16: SUPPORTED WITHIN 2DAYS | R16: SUPPORTED WITHIN 2DAYS | S16: 0 | T16: M001170038 | U16: Macarling, Federico Jr Romano | V16: 44156.539
A17: Guanzon Corporate Center | B17: REPAIRED | C17: OPEN | D17: M00120000395 | E17: 44156 | F17: GCC1 | G17: backload printer from Records. Epson LX300 - Unit2 | I17: REPAIR | J17: PRINTER | K17: 0 | N17: M00105000801 | P17: 44156 | Q17: SUPPORTED WITHIN 2DAYS | R17: SUPPORTED WITHIN 2DAYS | S17: 0 | T17: M001170038 | U17: Macarling, Federico Jr Romano | V17: 44156.522
A18: Guanzon Corporate Center | B18: REPAIRED | C18: OPEN | D18: M00120000394 | E18: 44156 | F18: GCC1 | G18: backload printer from Records. Epson LX300 - Unit1 | I18: REPAIR | J18: PRINTER | K18: 0 | N18: M00105000801 | P18: 44156 | Q18: SUPPORTED WITHIN 2DAYS | R18: SUPPORTED WITHIN 2DAYS | S18: 0 | T18: M001170038 | U18: Macarling, Federico Jr Romano | V18: 44156.521
A19: Guan Kai Office | B19: REPAIRED | C19: OPEN | D19: M00120000392 | E19: 44156 | F19: GK01 | G19: GK-HCM-Epson L3110 leak | I19: REPAIR | J19: PRINTER | K19: 0 | N19: M00105000801 | P19: 44156 | Q19: SUPPORTED WITHIN 2DAYS | R19: SUPPORTED WITHIN 2DAYS | S19: 0 | T19: M001170038 | U19: Macarling, Federico Jr Romano | V19: 44156.519
A20: LGK Tarlac - Honda | B20: REPAIRED | C20: OPEN | D20: M00120000388 | E20: 44156 | F20: M006 | G20: PRepare new SYSTEM UNIT - server pc | I20: INSTALLATION & CONFIGURATION | J20: SYSTEM UNIT | K20: 1 | N20: M00105000801 | P20: 44156 | Q20: SUPPORTED WITHIN 2DAYS | R20: SUPPORTED WITHIN 2DAYS | S20: 0 | T20: M001170038 | U20: Macarling, Federico Jr Romano | V20: 44156.462
A21: LGK Pozorrubio - Honda | B21: REPAIRED | C21: OPEN | D21: M00120000386 | E21: 44156 | F21: M038 | G21: windows 7. need to upgrade to windows 10 | H21: done. | I21: INSTALLATION & CONFIGURATION | J21: OTHER PERIPHERAL DEVICES | K21: 0 | M21: Done | N21: M00105000801 | O21: Macarling, F | P21: 44156 | Q21: SUPPORTED WITHIN 2DAYS | R21: SUPPORTED WITHIN 2DAYS | S21: 0 | T21: M001170038 | U21: Macarling, Federico Jr Romano | V21: 44156.378
A22: Guan Kai Office | B22: REPAIRED | C22: OPEN | D22: M00120000384 | E22: 44155 | F22: GK01 | G22: pull out Epson L3110 - HR Printer leak.. setup Epson L360 | I22: REPAIR | J22: PRINTER | K22: 0 | N22: M00115001493 | P22: 44155 | Q22: SUPPORTED WITHIN 2DAYS | R22: SUPPORTED WITHIN 2DAYS | S22: 0 | T22: M001170038 | U22: Macarling, Federico Jr Romano | V22: 44155.674
A23: Guan Kai Office | B23: REPAIRED | C23: OPEN | D23: M00120000383 | E23: 44155 | F23: GK01 | G23: setup Epson L360 | I23: INSTALLATION & CONFIGURATION | J23: PRINTER | K23: 0 | N23: M00115001493 | P23: 44155 | Q23: SUPPORTED WITHIN 2DAYS | R23: SUPPORTED WITHIN 2DAYS | S23: 0 | T23: M001170038 | U23: Macarling, Federico Jr Romano | V23: 44155.674
A24: Guan Kai Office | B24: REPAIRED | C24: OPEN | D24: M00120000375 | E24: 44155 | F24: GK01 | G24: pick up ink at micronics | I24: Others | J24: OTHER PERIPHERAL DEVICES | K24: 0 | N24: M00115001493 | P24: 44155 | Q24: SUPPORTED WITHIN 2DAYS | R24: SUPPORTED WITHIN 2DAYS | S24: 0 | T24: M001170038 | U24: Macarling, Federico Jr Romano | V24: 44155.607
A25: UEMI Rosario LU - Multi | B25: REPAIRED | C25: OPEN | D25: M00120000370 | E25: 44154 | F25: M110 | G25: need to repair printer | I25: REPAIR | J25: PRINTER | K25: 0 | N25: M00117000077 | P25: 44154 | Q25: SUPPORTED WITHIN 2DAYS | R25: SUPPORTED WITHIN 2DAYS | S25: 0 | T25: M001170038 | U25: Macarling, Federico Jr Romano | V25: 44154.647
A26: Guan Kai Office | B26: REPAIRED | C26: OPEN | D26: M00120000368 | E26: 44154 | F26: GK01 | G26: inquire 8port ethernet switch. for mcc baguio honda | I26: Others | J26: OTHER PERIPHERAL DEVICES | K26: 0 | N26: M00110017110 | P26: 44154 | Q26: SUPPORTED WITHIN 2DAYS | R26: SUPPORTED WITHIN 2DAYS | S26: 0 | T26: M001170038 | U26: Macarling, Federico Jr Romano | V26: 44154.581
A27: UEMI Dagupan - Suzuki | B27: REPAIRED | C27: OPEN | D27: M00120000367 | E27: 44154 | F27: M010 | G27: Antenna at GK pointing Suzuki dagupan - down. need to isolate and fix | I27: REPAIR | J27: NETWORK | K27: 0 | N27: M00107001868 | P27: 44154 | Q27: SUPPORTED WITHIN 2DAYS | R27: SUPPORTED WITHIN 2DAYS | S27: 0 | T27: M001170038 | U27: Macarling, Federico Jr Romano | V27: 44154.455
A28: MCC Dagupan - Kawasaki | B28: REPAIRED | C28: OPEN | D28: M00120000365 | E28: 44154 | F28: M126 | G28: Fix internet of MCC Dagupan Kawasaki | I28: REPAIR | J28: NETWORK | K28: 0 | N28: M01911000061 | P28: 44154 | Q28: SUPPORTED WITHIN 2DAYS | R28: SUPPORTED WITHIN 2DAYS | S28: 0 | T28: M001170038 | U28: Macarling, Federico Jr Romano | V28: 44154.454
A29: Guan Kai Office | B29: REPAIRED | C29: OPEN | D29: M00120000364 | E29: 44154 | F29: GK01 | G29: Fix local internet of M' Princess | I29: REPAIR | J29: NETWORK | K29: 0 | N29: M01911000061 | P29: 44154 | Q29: SUPPORTED WITHIN 2DAYS | R29: SUPPORTED WITHIN 2DAYS | S29: 0 | T29: M001170038 | U29: Macarling, Federico Jr Romano | V29: 44154.453
A30: Guan Kai Office | B30: REPAIRED | C30: OPEN | D30: M00120000363 | E30: 44154 | F30: GK01 | G30: Support/Assit Sir Phone about Zoom meeting | I30: SUPPORT ASSISTANCE(ACCESS, CALLS..) | J30: TECHNICAL SUPPORT | K30: 0 | N30: M00906001658 | P30: 44154 | Q30: SUPPORTED WITHIN 2DAYS | R30: SUPPORTED WITHIN 2DAYS | S30: 0 | T30: M001170038 | U30: Macarling, Federico Jr Romano | V30: 44154.453
A31: Guan Kai Office | B31: REPAIRED | C31: OPEN | D31: M00120000356 | E31: 44153 | F31: GK01 | G31: replace power supply - pc of multimedia | I31: REPAIR | J31: SYSTEM UNIT | K31: 0 | N31: M00105000084 | P31: 44153 | Q31: SUPPORTED WITHIN 2DAYS | R31: SUPPORTED WITHIN 2DAYS | S31: 0 | T31: M001170038 | U31: Macarling, Federico Jr Romano | V31: 44153.404
A32: Guanzon Corporate Center | B32: REPAIRED | C32: OPEN | D32: M00120000355 | E32: 44153 | F32: GCC1 | G32: for visit 2h- anolid.. need to replace router | I32: SUPPORT ASSISTANCE(ACCESS, CALLS..) | J32: TECHNICAL SUPPORT | K32: 0 | N32: M00105000084 | P32: 44153 | Q32: SUPPORTED WITHIN 2DAYS | R32: SUPPORTED WITHIN 2DAYS | S32: 0 | T32: M001170038 | U32: Macarling, Federico Jr Romano | V32: 44153.386
A33: UEMI Dagupan - Suzuki | B33: REPAIRED | C33: OPEN | D33: M00120000354 | E33: 44153 | F33: M010 | G33: fix ms office. reinstall | I33: SUPPORT ASSISTANCE(ACCESS, CALLS..) | J33: TECHNICAL SUPPORT | K33: 0 | N33: M00107001868 | P33: 44153 | Q33: SUPPORTED WITHIN 2DAYS | R33: SUPPORTED WITHIN 2DAYS | S33: 0 | T33: M001170038 | U33: Macarling, Federico Jr Romano | V33: 44153.385
... A37: Mobitek Nepo Mall Dagupan | B37: REPAIRED | C37: OPEN | D37: M00120000335 | E37: 44149 | F37: C008 | G37: fix telephone wirings of nepo dagupan mobitek - for terminal | I37: REPAIR | J37: NETWORK | K37: 0 | N37: M00119001128 | P37: 44149 | Q37: SUPPORTED WITHIN 2DAYS | R37: SUPPORTED WITHIN 2DAYS | S37: 0 | T37: M001170038 | U37: Macarling, Federico Jr Romano | V37: 44149.568
A38: Guan Kai Office | B38: REPAIRED | C38: OPEN | D38: M00120000330 | E38: 44149 | F38: GK01 | G38: Setup and install new PC of Support - PC 2 | I38: INSTALLATION & CONFIGURATION | J38: SYSTEM UNIT | K38: 0 | P38: 44149 | Q38: SUPPORTED WITHIN 2DAYS | R38: SUPPORTED WITHIN 2DAYS | S38: 0 | T38: M001170038 | U38: Macarling, Federico Jr Romano | V38: 44149.439
A39: Guan Kai Office | B39: REPAIRED | C39: OPEN | D39: M00120000329 | E39: 44149 | F39: GK01 | G39: Setup and install new PC of Support - PC 1 | I39: INSTALLATION & CONFIGURATION | J39: SYSTEM UNIT | K39: 0 | P39: 44149 | Q39: SUPPORTED WITHIN 2DAYS | R39: SUPPORTED WITHIN 2DAYS | S39: 0 | T39: M001170038 | U39: Macarling, Federico Jr Romano | V39: 44149.439
A40: UEMI San Nicolas - Yamaha | B40: REPAIRED | C40: OPEN | D40: M00120000326 | E40: 44148 | F40: M144 | G40: For diagnos - Server PC | I40: REPAIR | J40: SYSTEM UNIT | K40: 1 | N40: M00114001114 | P40: 44148 | Q40: SUPPORTED WITHIN 2DAYS | R40: SUPPORTED WITHIN 2DAYS | S40: 0 | T40: M001170038 | U40: Macarling, Federico Jr Romano | V40: 44148.624
A41: Guanzon Manila Office | B41: REPAIRED | C41: OPEN | D41: M00120000325 | E41: 44148 | F41: GMO1 | G41: Spare 2 of GMO - MIS | I41: INSTALLATION & CONFIGURATION | J41: SYSTEM UNIT | K41: 0 | N41: M00114001114 | P41: 44148 | Q41: SUPPORTED WITHIN 2DAYS | R41: SUPPORTED WITHIN 2DAYS | S41: 0 | T41: M001170038 | U41: Macarling, Federico Jr Romano | V41: 44148.623
A42: Guanzon Manila Office | B42: REPAIRED | C42: OPEN | D42: M00120000324 | E42: 44148 | F42: GMO1 | G42: Spare 1 of GMO - MIS | I42: INSTALLATION & CONFIGURATION | J42: SYSTEM UNIT | K42: 0 | N42: M00114001114 | P42: 44148 | Q42: SUPPORTED WITHIN 2DAYS | R42: SUPPORTED WITHIN 2DAYS | S42: 0 | T42: M001170038 | U42: Macarling, Federico Jr Romano | V42: 44148.623
A43: LGK Dagupan - Multi | B43: REPAIRED | C43: OPEN | D43: M00120000322 | E43: 44148 | F43: M002 | G43: PC 2 diagnosed as virus infected. client pc only | I43: SUPPORT ASSISTANCE(ACCESS, CALLS..) | J43: TECHNICAL SUPPORT | K43: 0 | N43: M00110017103 | P43: 44148 | Q43: SUPPORTED WITHIN 2DAYS | R43: SUPPORTED WITHIN 2DAYS | S43: 0 | T43: M001170038 | U43: Macarling, Federico Jr Romano | V43: 44148.454
...

Sheet Summary
A2: JO SUMMARY PER CATEGORY - NOV 2020
A3: Count of sTransNox | B3: Column Labels
A4: Row Labels | B4: CCTV | C4: GPS | D4: ISP CONCERN | E4: NETWORK | F4: OTHER PERIPHERAL DEVICES | G4: Others | H4: PRINTER | I4: SYSTEM UNIT | J4: TECHNICAL SUPPORT | K4: (blank) | L4: Grand Total
A5: INSTALLATION & CONFIGURATION | B5: 5 | C5: 6 | E5: 1 | F5: 6 | G5: 1 | H5: 2 | I5: 35 | L5: 56
A6: MAINTENANCE | B6: 1 | E6: 1 | H6: 2 | I6: 1 | L6: 5
A7: Others | C7: 8 | D7: 5 | E7: 3 | F7: 56 | G7: 63 | H7: 4 | I7: 3 | J7: 2 | L7: 144
A8: REPAIR | B8: 2 | D8: 22 | E8: 7 | F8: 3 | H8: 39 | I8: 37 | J8: 1 | L8: 111
A9: REPLACEMENT | B9: 2 | C9: 1 | F9: 3 | I9: 6 | L9: 12
A10: SUPPORT ASSISTANCE(ACCESS, CALLS..) | B10: 6 | C10: 1 | D10: 15 | E10: 9 | F10: 2 | H10: 24 | I10: 3 | J10: 42 | L10: 102
A11: TROUBLESHOOT | E11: 2 | H11: 1 | J11: 1 | L11: 4
A12: (blank) | K12: 5 | L12: 5
A13: Grand Total | B13: 16 | C13: 16 | D13: 42 | E13: 23 | F13: 70 | G13: 64 | H13: 72 | I13: 85 | J13: 46 | K13: 5 | L13: 439
A16: JO SUMMARY STATUS - NOV 2020
A17: Count of sTransNox | B17: Column Labels
A18: Row Labels | B18: NOT SUPPORTED WITHIN 2DAYS | C18: SUPPORTED WITHIN 2DAYS | D18: Grand Total | F18: Count of sTransNox | G18: Column Labels
A19: INSTALLATION & CONFIGURATION | B19: 20 | C19: 36 | D19: 56 | F19: Row Labels | G19: OPEN | H19: POSTED | I19: Grand Total
A20: MAINTENANCE | B20: 1 | C20: 4 | D20: 5 | F20: Cuison, Bernard Ramos | G20: 12 | I20: 12
A21: Others | B21: 45 | C21: 99 | D21: 144 | F21: Macarling, Federico Jr Romano | G21: 65 | H21: 110 | I21: 175
A22: REPAIR | B22: 35 | C22: 76 | D22: 111 | F22: Trinidad, Jan Carlo Aquino | G22: 25 | H22: 131 | I22: 156
A23: REPLACEMENT | B23: 2 | C23: 10 | D23: 12 | F23: Velasquez, Jayson Alon | G23: 14 | H23: 82 | I23: 96
A24: SUPPORT ASSISTANCE(ACCESS, CALLS..) | B24: 28 | C24: 74 | D24: 102 | F24: Grand Total | G24: 116 | H24: 323 | I24: 439
A25: TROUBLESHOOT | C25: 4 | D25: 4
A26: (blank) | B26: 1 | C26: 4 | D26: 5
A27: Grand Total | B27: 132 | C27: 307 | D27: 439
A30: CCTV Monitoring for the month of November
B31: Column Labels
B32: MONITORED | C32: NOT MONITORED | D32: NOT YET ADDED | E32: Grand Total
A33: Count of sBranchNm | B33: 32 | C33: 219 | D33: 22 | E33: 273
A37: Count of sBranchNm | B37: Column Labels
A38: Row Labels | B38: \N | C38: FOR REPLACEMENT | D38: FOR VISIT | E38: GOOD | F38: NO CCTV | G38: NO ISP | H38: RECORDING | I38: Grand Total
A39: Area 1 (MP) | D39: 7 | H39: 8 | I39: 15
A40: Area 2 (MP) | B40: 4 | D40: 4 | E40: 1 | H40: 12 | I40: 21
A41: Area 3 (MP) | D41: 5 | H41: 7 | I41: 12
A42: Area 4 (MP) | C42: 1 | D42: 14 | E42: 1 | G42: 2 | H42: 3 | I42: 21
A43: AREA 5 (MP) | B43: 1 | D43: 11 | H43: 3 | I43: 15
A44: Main 1 (MP) | B44: 7 | I44: 7
A45: Main Office | B45: 2 | H45: 2 | I45: 4
A46: NCR | D46: 5 | H46: 6 | I46: 11
A47: R1 - A | D47: 11 | F47: 1 | H47: 4 | I47: 16
A48: R1 - B | B48: 1 | D48: 5 | F48: 1 | H48: 7 | I48: 14
...

Sheet JO
A1: sBranchNm | B1: JO Status | C1: Status | D1: sTransNox | E1: dTransact | F1: sBranchCd | G1: sRequestX | H1: sDiagnose | I1: sJOTypexx | J1: sCategory | K1: cServerPC | L1: sProblemx | M1: sRemarksx | N1: sRqstdIDx | O1: sSupprtBy | P1: dPostedxx | Q1: ACTUAL STATUS | R1: ACTUAL STATUS no formula | S1: STATUS | T1: sModified | U1: Encoder | V1: dModified
A2: Guan Kai Office | B2: REPAIRED | C2: POSTED | D2: GK0120000576 | E2: 44137 | F2: GK01 | G2: No monitor display. | H2: nilinisan yung memory. | I2: REPAIR | J2: SYSTEM UNIT | K2: 0 | M2: Done | N2: M00119001680 | O2: Trinidad, Ja | P2: 44137 | Q2: =IF((P2-E2)>2,"NOT SUPPORTED WITHIN 2DAYS","SUPPORTED WITHIN 2DAYS") -> SUPPORTED WITHIN 2DAYS | R2: SUPPORTED WITHIN 2DAYS | S2: 0 | T2: GK01190015 | U2: =VLOOKUP(T2,personnel!A$1:B$4,2,FALSE) -> Trinidad, Jan Carlo Aquino | V2: 44137.389
A3: GMC San Fabian - Honda | B3: OTHERS | C3: POSTED | D3: GK0120000577 | E3: 44137 | F3: M064 | G3: Asset transfer replacement of old keyboard. | I3: Others | J3: Others | K3: 0 | M3: Done | N3: M00119001680 | O3: Trinidad, Ja | P3: 44137 | Q3: =IF((P3-E3)>2,"NOT SUPPORTED WITHIN 2DAYS","SUPPORTED WITHIN 2DAYS") -> SUPPORTED WITHIN 2DAYS | R3: SUPPORTED WITHIN 2DAYS | S3: 4 | T3: GK01190015 | U3: =VLOOKUP(T3,personnel!A$1:B$4,2,FALSE) -> Trinidad, Jan Carlo Aquino | V3: 44137.408
A4: Guanzon Corporate Center | B4: OTHERS | C4: POSTED | D4: GK0120000578 | E4: 44137 | F4: GCC1 | G4: Create PO, sticker, and asset transfer of repaired system unit 1 for Records department. | I4: SUPPORT ASSISTANCE(ACCESS, CALLS..) | J4: PRINTER | K4: 0 | M4: Done | O4: Trinidad, Ja | P4: 44139 | Q4: =IF((P4-E4)>2,"NOT SUPPORTED WITHIN 2DAYS","SUPPORTED WITHIN 2DAYS") -> SUPPORTED WITHIN 2DAYS | R4: SUPPORTED WITHIN 2DAYS | S4: 4 | T4: GK01190015 | U4: =VLOOKUP(T4,personnel!A$1:B$4,2,FALSE) -> Trinidad, Jan Carlo Aquino | V4: 44137.424
A5: Guan Kai Office | B5: OTHERS | C5: POSTED | D5: GK0120000579 | E5: 44137 | F5: GK01 | G5: Received backloads. | I5: SUPPORT ASSISTANCE(ACCESS, CALLS..) | J5: PRINTER | K5: 0 | M5: Done | O5: Trinidad, Ja | P5: 44139 | Q5: =IF((P5-E5)>2,"NOT SUPPORTED WITHIN 2DAYS","SUPPORTED WITHIN 2DAYS") -> SUPPORTED WITHIN 2DAYS | R5: SUPPORTED WITHIN 2DAYS | S5: 4 | T5: GK01190015 | U5: =VLOOKUP(T5,personnel!A$1:B$4,2,FALSE) -> Trinidad, Jan Carlo Aquino | V5: 44137.613
A6: GMC Baguio - Multi | B6: OTHERS | C6: POSTED | D6: GK0120000580 | E6: 44137 | F6: M175 | G6: Spare system unit. copy files para mapadala sa kanila. | I6: Others | J6: Others | K6: 0 | M6: Done | O6: Trinidad, Ja | P6: 44154 | Q6: =IF((P6-E6)>2,"NOT SUPPORTED WITHIN 2DAYS","SUPPORTED WITHIN 2DAYS") -> NOT SUPPORTED WITHIN 2DAYS | R6: NOT SUPPORTED WITHIN 2DAYS | S6: 4 | T6: GK01190015 | U6: =VLOOKUP(T6,personnel!A$1:B$4,2,FALSE) -> Trinidad, Jan Carlo Aquino | V6: 44137.614
A7: MCC Sta. Barbara- Honda | B7: NEW INSTALL | C7: POSTED | D7: GK0120000581 | E7: 44138 | F7: M111 | G7: For diagnose. | H7: nireformat ni sir Rico. ininstall ko mga softwares. | I7: SUPPORT ASSISTANCE(ACCESS, CALLS..) | J7: PRINTER | K7: 0 | M7: Done | O7: Trinidad, Ja | P7: 44139 | Q7: =IF((P7-E7)>2,"NOT SUPPORTED WITHIN 2DAYS","SUPPORTED WITHIN 2DAYS") -> SUPPORTED WITHIN 2DAYS | R7: SUPPORTED WITHIN 2DAYS | S7: 3 | T7: GK01190015 | U7: =VLOOKUP(T7,personnel!A$1:B$4,2,FALSE) -> Trinidad, Jan Carlo Aquino | V7: 44138.484
A8: Guan Kai Office | B8: REPAIRED | C8: POSTED | D8: GK0120000582 | E8: 44138 | F8: GK01 | G8: connect laptop of sir Gene sa printer ni mam Shirley. | I8: SUPPORT ASSISTANCE(ACCESS, CALLS..) | J8: PRINTER | K8: 0 | M8: Done | O8: Trinidad, Ja | P8: 44139 | Q8: =IF((P8-E8)>2,"NOT SUPPORTED WITHIN 2DAYS","SUPPORTED WITHIN 2DAYS") -> SUPPORTED WITHIN 2DAYS | R8: SUPPORTED WITHIN 2DAYS | S8: 0 | T8: GK01190015 | U8: =VLOOKUP(T8,personnel!A$1:B$4,2,FALSE) -> Trinidad, Jan Carlo Aquino | V8: 44138.486
A9: Mobitek Robinsons Santiago | B9: OTHERS | C9: POSTED | D9: GK0120000583 | E9: 44138 | F9: C041 | G9: Asset transfer repaired UPS with new Battery. | I9: SUPPORT ASSISTANCE(ACCESS, CALLS..) | J9: PRINTER | K9: 0 | M9: Done | O9: Trinidad, Ja | P9: 44139 | Q9: =IF((P9-E9)>2,"NOT SUPPORTED WITHIN 2DAYS","SUPPORTED WITHIN 2DAYS") -> SUPPORTED WITHIN 2DAYS | R9: SUPPORTED WITHIN 2DAYS | S9: 4 | T9: GK01190015 | U9: =VLOOKUP(T9,personnel!A$1:B$4,2,FALSE) -> Trinidad, Jan Carlo Aquino | V9: 44138.49
A10: UEMI San Fabian - Yamaha | B10: OTHERS | C10: POSTED | D10: GK0120000584 | E10: 44139 | F10: M174 | G10: Put stickers on 1 set of computer. except system unit already have. | I10: SUPPORT ASSISTANCE(ACCESS, CALLS..) | J10: PRINTER | K10: 0 | M10: Done | O10: Trinidad, Ja | P10: 44139 | Q10: =IF((P10-E10)>2,"NOT SUPPORTED WITHIN 2DAYS","SUPPORTED WITHIN 2DAYS") -> SUPPORTED WITHIN 2DAYS | R10: SUPPORTED WITHIN 2DAYS | S10: 4 | T10: GK01190015 | U10: =VLOOKUP(T10,personnel!A$1:B$4,2,FALSE) -> Trinidad, Jan Carlo Aquino | V10: 44139.416
A11: UEMI San Fabian - Yamaha | B11: OTHERS | C11: POSTED | D11: GK0120000585 | E11: 44139 | F11: M174 | G11: Asset transfer of new 1 set of computer for new branch. | I11: SUPPORT ASSISTANCE(ACCESS, CALLS..) | J11: PRINTER | K11: 0 | M11: Done | O11: Trinidad, Ja | P11: 44139 | Q11: =IF((P11-E11)>2,"NOT SUPPORTED WITHIN 2DAYS","SUPPORTED WITHIN 2DAYS") -> SUPPORTED WITHIN 2DAYS | R11: SUPPORTED WITHIN 2DAYS | S11: 4 | T11: GK01190015 | U11: =VLOOKUP(T11,personnel!A$1:B$4,2,FALSE) -> Trinidad, Jan Carlo Aquino | V11: 44139.416
A12: GMC Dagupan - Honda | B12: OTHERS | C12: POSTED | D12: GK0120000586 | E12: 44139 | F12: M001 | G12: Create PO receiving of old UPS. | I12: SUPPORT ASSISTANCE(ACCESS, CALLS..) | J12: PRINTER | K12: 0 | M12: Done | O12: Trinidad, Ja | P12: 44139 | Q12: =IF((P12-E12)>2,"NOT SUPPORTED WITHIN 2DAYS","SUPPORTED WITHIN 2DAYS") -> SUPPORTED WITHIN 2DAYS | R12: SUPPORTED WITHIN 2DAYS | S12: 4 | T12: GK01190015 | U12: =VLOOKUP(T12,personnel!A$1:B$4,2,FALSE) -> Trinidad, Jan Carlo Aquino | V12: 44139.419
A13: GMC Dagupan - Honda | B13: OTHERS | C13: POSTED | D13: GK0120000587 | E13: 44139 | F13: M001 | G13: Put sticker serial of UPS. | I13: SUPPORT ASSISTANCE(ACCESS, CALLS..) | J13: PRINTER | K13: 0 | M13: Done | O13: Trinidad, Ja | P13: 44139 | Q13: =IF((P13-E13)>2,"NOT SUPPORTED WITHIN 2DAYS","SUPPORTED WITHIN 2DAYS") -> SUPPORTED WITHIN 2DAYS | R13: SUPPORTED WITHIN 2DAYS | S13: 4 | T13: GK01190015 | U13: =VLOOKUP(T13,personnel!A$1:B$4,2,FALSE) -> Trinidad, Jan Carlo Aquino | V13: 44139.419
A14: GMC Dagupan - Honda | B14: OTHERS | C14: POSTED | D14: GK0120000588 | E14: 44139 | F14: M001 | G14: Asset transfer of old UPS. | I14: SUPPORT ASSISTANCE(ACCESS, CALLS..) | J14: PRINTER | K14: 0 | M14: Done | O14: Trinidad, Ja | P14: 44139 | Q14: =IF((P14-E14)>2,"NOT SUPPORTED WITHIN 2DAYS","SUPPORTED WITHIN 2DAYS") -> SUPPORTED WITHIN 2DAYS | R14: SUPPORTED WITHIN 2DAYS | S14: 4 | T14: GK01190015 | U14: =VLOOKUP(T14,personnel!A$1:B$4,2,FALSE) -> Trinidad, Jan Carlo Aquino | V14: 44139.419
A15: GMC San Fabian - Honda | B15: NEW INSTALL | C15: POSTED | D15: GK0120000589 | E15: 44138 | F15: M064 | G15: For checking installed system unit. | I15: SUPPORT ASSISTANCE(ACCESS, CALLS..) | J15: PRINTER | K15: 0 | M15: Done. | O15: Trinidad, Ja | P15: 44139 | Q15: =IF((P15-E15)>2,"NOT SUPPORTED WITHIN 2DAYS","SUPPORTED WITHIN 2DAYS") -> SUPPORTED WITHIN 2DAYS | R15: SUPPORTED WITHIN 2DAYS | S15: 3 | T15: GK01190015 | U15: =VLOOKUP(T15,personnel!A$1:B$4,2,FALSE) -> Trinidad, Jan Carlo Aquino | V15: 44139.454
A16: Guanzon Central Office | B16: OTHERS | C16: POSTED | D16: GK0120000590 | E16: 44139 | F16: GCO1 | G16: Asset transfer repaired system unit with monitor. | I16: SUPPORT ASSISTANCE(ACCESS, CALLS..) | J16: PRINTER | K16: 0 | M16: Done | O16: Trinidad, Ja | P16: 44139 | Q16: =IF((P16-E16)>2,"NOT SUPPORTED WITHIN 2DAYS","SUPPORTED WITHIN 2DAYS") -> SUPPORTED WITHIN 2DAYS | R16: SUPPORTED WITHIN 2DAYS | S16: 4 | T16: GK01190015 | U16: =VLOOKUP(T16,personnel!A$1:B$4,2,FALSE) -> Trinidad, Jan Carlo Aquino | V16: 44139.566
A17: MCC Sta. Barbara- Honda | B17: OTHERS | C17: POSTED | D17: GK0120000591 | E17: 44139 | F17: M111 | G17: install Softwares. | I17: MAINTENANCE | J17: PRINTER | K17: 0 | M17: Done ready for checking. | O17: Trinidad, Ja | P17: 44139 | Q17: =IF((P17-E17)>2,"NOT SUPPORTED WITHIN 2DAYS","SUPPORTED WITHIN 2DAYS") -> SUPPORTED WITHIN 2DAYS | R17: SUPPORTED WITHIN 2DAYS | S17: 4 | T17: GK01190015 | U17: =VLOOKUP(T17,personnel!A$1:B$4,2,FALSE) -> Trinidad, Jan Carlo Aquino | V17: 44139.57
A18: Guan Kai Office | B18: OTHERS | C18: POSTED | D18: GK0120000592 | E18: 44139 | F18: GK01 | G18: Refill yellow ink. | I18: SUPPORT ASSISTANCE(ACCESS, CALLS..) | J18: PRINTER | K18: 0 | M18: Done | O18: Trinidad, Ja | P18: 44139 | Q18: =IF((P18-E18)>2,"NOT SUPPORTED WITHIN 2DAYS","SUPPORTED WITHIN 2DAYS") -> SUPPORTED WITHIN 2DAYS | R18: SUPPORTED WITHIN 2DAYS | S18: 4 | T18: GK01190015 | U18: =VLOOKUP(T18,personnel!A$1:B$4,2,FALSE) -> Trinidad, Jan Carlo Aquino | V18: 44139.587
A19: Guan Kai Office | B19: REPAIRED | C19: POSTED | D19: GK0120000593 | E19: 44139 | F19: GK01 | G19: Connect pc of sir Charles of HR to printer of mam shirley. | I19: SUPPORT ASSISTANCE(ACCESS, CALLS..) | J19: PRINTER | K19: 0 | M19: Done | N19: M00118001281 | O19: Trinidad, Ja | P19: 44139 | Q19: =IF((P19-E19)>2,"NOT SUPPORTED WITHIN 2DAYS","SUPPORTED WITHIN 2DAYS") -> SUPPORTED WITHIN 2DAYS | R19: SUPPORTED WITHIN 2DAYS | S19: 0 | T19: GK01190015 | U19: =VLOOKUP(T19,personnel!A$1:B$4,2,FALSE) -> Trinidad, Jan Carlo Aquino | V19: 44139.625
A20: UEMI Cauayan - Multi | B20: OTHERS | C20: POSTED | D20: GK0120000594 | E20: 44140 | F20: M051 | G20: tumawag yung branch na ipadala daw po sa kanila yung binackload nilang 5 GPS. | I20: INSTALLATION & CONFIGURATION | J20: SYSTEM UNIT | K20: 0 | M20: Done | O20: Trinidad, Ja | P20: 44144 | Q20: =IF((P20-E20)>2,"NOT SUPPORTED WITHIN 2DAYS","SUPPORTED WITHIN 2DAYS") -> NOT SUPPORTED WITHIN 2DAYS | R20: NOT SUPPORTED WITHIN 2DAYS | S20: 4 | T20: GK01190015 | U20: =VLOOKUP(T20,personnel!A$1:B$4,2,FALSE) -> Trinidad, Jan Carlo Aquino | V20: 44140.349
A21: UEMI Mangaldan - Suzuki | B21: REPAIRED | C21: POSTED | D21: GK0120000595 | E21: 44140 | F21: M156 | G21: For backload - start up repair. | I21: INSTALLATION & CONFIGURATION | J21: SYSTEM UNIT | K21: 0 | M21: Done | O21: Trinidad, Ja | P21: 44144 | Q21: =IF((P21-E21)>2,"NOT SUPPORTED WITHIN 2DAYS","SUPPORTED WITHIN 2DAYS") -> NOT SUPPORTED WITHIN 2DAYS | R21: NOT SUPPORTED WITHIN 2DAYS | S21: 0 | T21: GK01190015 | U21: =VLOOKUP(T21,personnel!A$1:B$4,2,FALSE) -> Trinidad, Jan Carlo Aquino | V21: 44140.38
A22: Guan Kai Office | B22: REPAIRED | C22: POSTED | D22: GK0120000596 | E22: 44140 | F22: GK01 | G22: Connect pc ni sir Cholo sa printer ng Hardware. | I22: INSTALLATION & CONFIGURATION | J22: SYSTEM UNIT | K22: 0 | M22: Done | N22: M00119000629 | O22: Trinidad, Ja | P22: 44144 | Q22: =IF((P22-E22)>2,"NOT SUPPORTED WITHIN 2DAYS","SUPPORTED WITHIN 2DAYS") -> NOT SUPPORTED WITHIN 2DAYS | R22: NOT SUPPORTED WITHIN 2DAYS | S22: 0 | T22: GK01190015 | U22: =VLOOKUP(T22,personnel!A$1:B$4,2,FALSE) -> Trinidad, Jan Carlo Aquino | V22: 44140.464
A23: Guan Kai Office | B23: REPAIRED | C23: POSTED | D23: GK0120000597 | E23: 44140 | F23: GK01 | G23: Connect printer of mam Badeth of HR dept. sa printer ng MIS. | I23: INSTALLATION & CONFIGURATION | J23: SYSTEM UNIT | K23: 0 | M23: Done | N23: M00116002291 | O23: Trinidad, Ja | P23: 44144 | Q23: =IF((P23-E23)>2,"NOT SUPPORTED WITHIN 2DAYS","SUPPORTED WITHIN 2DAYS") -> NOT SUPPORTED WITHIN 2DAYS | R23: NOT SUPPORTED WITHIN 2DAYS | S23: 0 | T23: GK01190015 | U23: =VLOOKUP(T23,personnel!A$1:B$4,2,FALSE) -> Trinidad, Jan Carlo Aquino | V23: 44140.464
A24: Guan Kai Office | B24: REPAIRED | C24: POSTED | D24: GK0120000598 | E24: 44140 | F24: GK01 | G24: puno na yung pod at need ireset. | I24: REPAIR | J24: SYSTEM UNIT | K24: 0 | M24: DOne | N24: M00116002291 | O24: Trinidad, Ja | P24: 44140 | Q24: =IF((P24-E24)>2,"NOT SUPPORTED WITHIN 2DAYS","SUPPORTED WITHIN 2DAYS") -> SUPPORTED WITHIN 2DAYS | R24: SUPPORTED WITHIN 2DAYS | S24: 0 | T24: GK01190015 | U24: =VLOOKUP(T24,personnel!A$1:B$4,2,FALSE) -> Trinidad, Jan Carlo Aquino | V24: 44140.467
A25: UEMI Cauayan - Multi | B25: OTHERS | C25: POSTED | D25: GK0120000599 | E25: 44140 | F25: M051 | G25: Document transfer GPS. | I25: INSTALLATION & CONFIGURATION | J25: SYSTEM UNIT | K25: 0 | M25: Done | O25: Trinidad, Ja | P25: 44144 | Q25: =IF((P25-E25)>2,"NOT SUPPORTED WITHIN 2DAYS","SUPPORTED WITHIN 2DAYS") -> NOT SUPPORTED WITHIN 2DAYS | R25: NOT SUPPORTED WITHIN 2DAYS | S25: 4 | T25: GK01190015 | U25: =VLOOKUP(T25,personnel!A$1:B$4,2,FALSE) -> Trinidad, Jan Carlo Aquino | V25: 44140.606
A26: Guan Kai Office | B26: REPAIRED | C26: POSTED | D26: GK0120000600 | E26: 44140 | F26: GK01 | G26: No monitor display of mam shirley's PC. | H26: kailangang linisan memory para mag open . | I26: REPAIR | J26: SYSTEM UNIT | K26: 0 | M26: Done | O26: Trinidad, Ja | P26: 44140 | Q26: =IF((P26-E26)>2,"NOT SUPPORTED WITHIN 2DAYS","SUPPORTED WITHIN 2DAYS") -> SUPPORTED WITHIN 2DAYS | R26: SUPPORTED WITHIN 2DAYS | S26: 0 | T26: GK01190015 | U26: =VLOOKUP(T26,personnel!A$1:B$4,2,FALSE) -> Trinidad, Jan Carlo Aquino | V26: 44140.68
A27: UEMI Malasiqui - Multi | B27: REPAIRED | C27: POSTED | D27: GK0120000601 | E27: 44141 | F27: M053 | G27: Hindi daw po magamit. | I27: Others | J27: Others | K27: 0 | M27: Done | O27: Trinidad, Ja | P27: 44154 | Q27: =IF((P27-E27)>2,"NOT SUPPORTED WITHIN 2DAYS","SUPPORTED WITHIN 2DAYS") -> NOT SUPPORTED WITHIN 2DAYS | R27: NOT SUPPORTED WITHIN 2DAYS | S27: 0 | T27: GK01190015 | U27: =VLOOKUP(T27,personnel!A$1:B$4,2,FALSE) -> Trinidad, Jan Carlo Aquino | V27: 44141.387
A28: MCC Sta. Barbara- Honda | B28: OTHERS | C28: POSTED | D28: GK0120000602 | E28: 44141 | F28: M111 | G28: Asset transfer of repaired backload system unit. | I28: INSTALLATION & CONFIGURATION | J28: SYSTEM UNIT | K28: 0 | M28: Done | O28: Trinidad, Ja | P28: 44144 | Q28: =IF((P28-E28)>2,"NOT SUPPORTED WITHIN 2DAYS","SUPPORTED WITHIN 2DAYS") -> NOT SUPPORTED WITHIN 2DAYS | R28: NOT SUPPORTED WITHIN 2DAYS | S28: 4 | T28: GK01190015 | U28: =VLOOKUP(T28,personnel!A$1:B$4,2,FALSE) -> Trinidad, Jan Carlo Aquino | V28: 44141.387
A29: Guan Kai Office | B29: OTHERS | C29: POSTED | D29: GK0120000603 | E29: 44141 | F29: GK01 | G29: Document transfer system unit for CFF. | I29: INSTALLATION & CONFIGURATION | J29: SYSTEM UNIT | K29: 0 | M29: Done | O29: Trinidad, Ja | P29: 44144 | Q29: =IF((P29-E29)>2,"NOT SUPPORTED WITHIN 2DAYS","SUPPORTED WITHIN 2DAYS") -> NOT SUPPORTED WITHIN 2DAYS | R29: NOT SUPPORTED WITHIN 2DAYS | S29: 4 | T29: GK01190015 | U29: =VLOOKUP(T29,personnel!A$1:B$4,2,FALSE) -> Trinidad, Jan Carlo Aquino | V29: 44141.48
A30: MCC Balasan - Multi | B30: OTHERS | C30: POSTED | D30: GK0120000604 | E30: 44141 | F30: M119 | G30: Create sticker and asset transfer of requested 1 keyboard for replacement. | I30: INSTALLATION & CONFIGURATION | J30: SYSTEM UNIT | K30: 0 | M30: Done | O30: Trinidad, Ja | P30: 44144 | Q30: =IF((P30-E30)>2,"NOT SUPPORTED WITHIN 2DAYS","SUPPORTED WITHIN 2DAYS") -> NOT SUPPORTED WITHIN 2DAYS | R30: NOT SUPPORTED WITHIN 2DAYS | S30: 4 | T30: GK01190015 | U30: =VLOOKUP(T30,personnel!A$1:B$4,2,FALSE) -> Trinidad, Jan Carlo Aquino | V30: 44141.649
A31: MCC Balasan - Multi | B31: OTHERS | C31: POSTED | D31: GK0120000605 | E31: 44141 | F31: M119 | G31: Create asset transfer and sticker of repaired system unit. | I31: INSTALLATION & CONFIGURATION | J31: SYSTEM UNIT | K31: 0 | M31: Done | O31: Trinidad, Ja | P31: 44144 | Q31: =IF((P31-E31)>2,"NOT SUPPORTED WITHIN 2DAYS","SUPPORTED WITHIN 2DAYS") -> NOT SUPPORTED WITHIN 2DAYS | R31: NOT SUPPORTED WITHIN 2DAYS | S31: 4 | T31: GK01190015 | U31: =VLOOKUP(T31,personnel!A$1:B$4,2,FALSE) -> Trinidad, Jan Carlo Aquino | V31: 44141.656
A32: UEMI Calasiao - Multi | B32: NEW INSTALL | C32: POSTED | D32: GK0120000606 | E32: 44141 | F32: M080 | G32: Create PO of old UPS w/o serial. | I32: INSTALLATION & CONFIGURATION | J32: SYSTEM UNIT | K32: 0 | M32: Done | O32: Trinidad, Ja | P32: 44144 | Q32: =IF((P32-E32)>2,"NOT SUPPORTED WITHIN 2DAYS","SUPPORTED WITHIN 2DAYS") -> NOT SUPPORTED WITHIN 2DAYS | R32: NOT SUPPORTED WITHIN 2DAYS | S32: 3 | T32: GK01190015 | U32: =VLOOKUP(T32,personnel!A$1:B$4,2,FALSE) -> Trinidad, Jan Carlo Aquino | V32: 44141.662
A33: UEMI Calasiao - Multi | B33: OTHERS | C33: POSTED | D33: GK0120000607 | E33: 44141 | F33: M080 | G33: Create asset transfer of repaired old system unit. | I33: INSTALLATION & CONFIGURATION | J33: SYSTEM UNIT | K33: 0 | M33: Done | O33: Trinidad, Ja | P33: 44144 | Q33: =IF((P33-E33)>2,"NOT SUPPORTED WITHIN 2DAYS","SUPPORTED WITHIN 2DAYS") -> NOT SUPPORTED WITHIN 2DAYS | R33: NOT SUPPORTED WITHIN 2DAYS | S33: 4 | T33: GK01190015 | U33: =VLOOKUP(T33,personnel!A$1:B$4,2,FALSE) -> Trinidad, Jan Carlo Aquino | V33: 44141.662
A34: Guan Kai Office | B34: OTHERS | C34: POSTED | D34: GK0120000608 | E34: 44144 | F34: GK01 | G34: Create PO and sticker of 2 new Asus charger. | I34: INSTALLATION & CONFIGURATION | J34: SYSTEM UNIT | K34: 0 | M34: Done | N34: M00113001232 | O34: Trinidad, Ja | P34: 44144 | Q34: =IF((P34-E34)>2,"NOT SUPPORTED WITHIN 2DAYS","SUPPORTED WITHIN 2DAYS") -> SUPPORTED WITHIN 2DAYS | R34: SUPPORTED WITHIN 2DAYS | S34: 4 | T34: GK01190015 | U34: =VLOOKUP(T34,personnel!A$1:B$4,2,FALSE) -> Trinidad, Jan Carlo Aquino | V34: 44144.362
A35: Guan Kai Office | B35: OTHERS | C35: POSTED | D35: GK0120000609 | E35: 44144 | F35: GK01 | G35: Create PO and sticker of 10 new HDD. | I35: Others | J35: Others | K35: 0 | M35: Done | N35: M00113001232 | O35: Trinidad, Ja | P35: 44154 | Q35: =IF((P35-E35)>2,"NOT SUPPORTED WITHIN 2DAYS","SUPPORTED WITHIN 2DAYS") -> NOT SUPPORTED WITHIN 2DAYS | R35: NOT SUPPORTED WITHIN 2DAYS | S35: 4 | T35: GK01190015 | U35: =VLOOKUP(T35,personnel!A$1:B$4,2,FALSE) -> Trinidad, Jan Carlo Aquino | V35: 44144.363
A36: Guanzon Corporate Center | B36: REPAIRED | C36: POSTED | D36: GK0120000610 | E36: 44142 | F36: GCC1 | G36: install altertv Tools of teamviewer of ma'am airah of audit. | H36: walang Altertool kaya hindi maka connect mga support sa PC ni mam Airah. | I36: INSTALLATION & CONFIGURATION | J36: SYSTEM UNIT | K36: 0 | M36: Done | N36: M01911000061 | O36: Trinidad, Ja | P36: 44144 | Q36: =IF((P36-E36)>2,"NOT SUPPORTED WITHIN 2DAYS","SUPPORTED WITHIN 2DAYS") -> SUPPORTED WITHIN 2DAYS | R36: SUPPORTED WITHIN 2DAYS | S36: 0 | T36: GK01190015 | U36: =VLOOKUP(T36,personnel!A$1:B$4,2,FALSE) -> Trinidad, Jan Carlo Aquino | V36: 44144.372
A37: Guanzon Corporate Center | B37: NEW INSTALL | C37: POSTED | D37: GK0120000611 | E37: 44142 | F37: GCC1 | G37: install OS and softwares of PC 1 at Washington Warehouse. | I37: INSTALLATION & CONFIGURATION | J37: SYSTEM UNIT | K37: 0 | M37: Done | N37: M00110017110 | O37: Trinidad, Ja | P37: 44144 | Q37: =IF((P37-E37)>2,"NOT SUPPORTED WITHIN 2DAYS","SUPPORTED WITHIN 2DAYS") -> SUPPORTED WITHIN 2DAYS | R37: SUPPORTED WITHIN 2DAYS | S37: 3 | T37: GK01190015 | U37: =VLOOKUP(T37,personnel!A$1:B$4,2,FALSE) -> Trinidad, Jan Carlo Aquino | V37: 44144.373
A38: Guanzon Corporate Center | B38: NEW INSTALL | C38: POSTED | D38: GK0120000612 | E38: 44142 | F38: GCC1 | G38: install OS and softwares of PC 2 at Washington Warehouse. | I38: INSTALLATION & CONFIGURATION | J38: SYSTEM UNIT | K38: 0 | M38: Done | N38: M00110017110 | O38: Trinidad, Ja | P38: 44144 | Q38: =IF((P38-E38)>2,"NOT SUPPORTED WITHIN 2DAYS","SUPPORTED WITHIN 2DAYS") -> SUPPORTED WITHIN 2DAYS | R38: SUPPORTED WITHIN 2DAYS | S38: 3 | T38: GK01190015 | U38: =VLOOKUP(T38,personnel!A$1:B$4,2,FALSE) -> Trinidad, Jan Carlo Aquino | V38: 44144.373
A39: Guanzon Corporate Center | B39: NEW INSTALL | C39: POSTED | D39: GK0120000613 | E39: 44142 | F39: GCC1 | G39: Install OS and softwares of PC 3 for stocks. | I39: INSTALLATION & CONFIGURATION | J39: SYSTEM UNIT | K39: 0 | M39: Done | N39: M00110017110 | O39: Trinidad, Ja | P39: 44144 | Q39: =IF((P39-E39)>2,"NOT SUPPORTED WITHIN 2DAYS","SUPPORTED WITHIN 2DAYS") -> SUPPORTED WITHIN 2DAYS | R39: SUPPORTED WITHIN 2DAYS | S39: 3 | T39: GK01190015 | U39: =VLOOKUP(T39,personnel!A$1:B$4,2,FALSE) -> Trinidad, Jan Carlo Aquino | V39: 44144.382
A40: Guanzon Corporate Center | B40: NEW INSTALL | C40: POSTED | D40: GK0120000614 | E40: 44142 | F40: GCC1 | G40: Install OS and softwares of pc 4 at Washington Warehouse. | I40: INSTALLATION & CONFIGURATION | J40: SYSTEM UNIT | K40: 0 | M40: Done | N40: M00110017110 | O40: Trinidad, Ja | P40: 44144 | Q40: =IF((P40-E40)>2,"NOT SUPPORTED WITHIN 2DAYS","SUPPORTED WITHIN 2DAYS") -> SUPPORTED WITHIN 2DAYS | R40: SUPPORTED WITHIN 2DAYS | S40: 3 | T40: GK01190015 | U40: =VLOOKUP(T40,personnel!A$1:B$4,2,FALSE) -> Trinidad, Jan Carlo Aquino | V40: 44144.383
...

Sheet personnel
A1: M001170038 | B1: Macarling, Federico Jr Romano
A2: GK01190010 | B2: Cuison, Bernard Ramos
A3: M001190058 | B3: Velasquez, Jayson Alon
A4: GK01190015 | B4: Trinidad, Jan Carlo Aquino

Sheet CCTV
A1: sAreaDesc | B1: sBranchNm | C1: sAreaCode | D1: sBranchCd | E1: dDateInst | F1: sBrandNme | G1: nNoCamera | H1: sDVRPassw | I1: sWIFIName | J1: sWIFIPass | K1: sRemarksx | L1: sHIKStatx | M1: sCCTVStat | N1: dMonitorx | O1: sMonitorx | P1: sVerifyCd | Q1: sWthTAlrm | R1: sModified | S1: dModified | T1: STATUS
A2: Area 1 (MP) | B2: Huawei - SM Baguio | C2: 10 | D2: C079 | E2: 43704 | F2: hikvision | G2: 3 | H2: gtcAdmin19 | I2: qwerty | J2: qwerty | K2: NO VIDEO CAMERA 2.. 3 camera installed only | L2: ONLINE | M2: RECORDING | N2: 44159 | O2: Macarling, Federico | P2: 123456 | Q2: no | R2: M001170038 | S2: 44159.586 | T2: MONITORED
A3: Area 1 (MP) | B3: Huawei - SM Center Dagupan | C3: 10 | D3: C085 | E3: 44075 | F3: HIKVISION | G3: 4 | H3: ggcAdmin85 | I3: GUANZON_C085 | J3: huawei4826966477 | K3: GOOD | L3: ONLINE | M3: RECORDING | N3: 44159 | O3: Macarling, Federico | P3: 123456 | Q3: n/a | R3: M001170038 | S3: 44159.584 | T3: MONITORED
A4: Area 1 (MP) | B4: Mobitek City Mall | C4: 10 | D4: C002 | E4: 43731 | F4: hikvision | G4: 3 | H4: gtcAdmin02 | I4: qwerty | J4: 1234 | K4: good. 3camera only installed | L4: ONLINE | M4: RECORDING | N4: 44120 | O4: Macarling, Federico | P4: 123456 | Q4: - | R4: M001170038 | S4: 44120.453 | T4: NOT MONITORED
A5: Area 1 (MP) | B5: Mobitek JTC Tagudin | C5: 10 | D5: C047 | E5: 43704 | F5: DVR-DVS | G5: 3 | H5: gtcAdmin47 | I5: qwerty | J5: qwerty | K5: DVR DVS recorder/ platform not supported. FOR REPLACEMENT DVR | L5: OFFLINE | M5: FOR VISIT | N5: 44120 | O5: Macarling, Federico | P5: 123456 | Q5: - | R5: M001170038 | S5: 44120.453 | T5: NOT MONITORED
A6: Area 1 (MP) | B6: Mobitek Metroplaza | C6: 10 | D6: C049 | E6: 43731 | F6: hikvison | G6: 4 | H6: gtcAdmin49 | I6: qwerty | J6: qwerty | K6: camera 3 NO VIDEO | L6: OFFLINE | M6: FOR VISIT | N6: 44120 | O6: Macarling, Federico | P6: 123456 | Q6: - | R6: M001170038 | S6: 44120.454 | T6: NOT MONITORED
A7: Area 1 (MP) | B7: Mobitek Nepo Mall Dagupan | C7: 10 | D7: C008 | E7: 43731 | F7: hikvision | G7: 3 | H7: gtcAdmin08 | I7: qwerty | J7: 48205823646 | K7: offline to hikconnect | L7: OFFLINE | M7: FOR VISIT | N7: 44120 | O7: Macarling, Federico | P7: 123456 | Q7: - | R7: M001170038 | S7: 44120.672 | T7: NOT MONITORED
A8: Area 1 (MP) | B8: Mobitek Perez | C8: 10 | D8: C001 | E8: 43731 | F8: hikvision | G8: 4 | H8: gtcAdmin01 | I8: qwerty | J8: mobitekdagupanmain01 | K8: good | L8: ONLINE | M8: RECORDING | N8: 44120 | O8: Macarling, Federico | P8: 123456 | Q8: - | R8: M001170038 | S8: 44120.458 | T8: NOT MONITORED
A9: Area 1 (MP) | B9: Mobitek SM Center Dagupan | C9: 10 | D9: C084 | E9: 43466 | F9: HIKVISION | G9: 4 | H9: gtcAdmin84 | I9: GUANZON_C084 | J9: mobitek48208423646 | K9: GOOD | L9: ONLINE | M9: RECORDING | N9: 44159 | O9: Macarling, Federico | P9: 123456 | Q9: n/a | R9: M001170038 | S9: 44159.584 | T9: MONITORED
A10: Area 1 (MP) | B10: Mobitek Stern Mall Candon | C10: 10 | D10: C011 | E10: 43697 | F10: hikvision | G10: 3 | H10: gtcAdmin11 | I10: qwerty | J10: G48201123646G | K10: cam 1 and 4 video loss. For Visit | L10: OFFLINE | M10: FOR VISIT | N10: 44159 | O10: Macarling, Federico | P10: 123456 | Q10: 1 | R10: M001170038 | S10: 44159.585 | T10: MONITORED
A11: Area 1 (MP) | B11: Mobitek Vigan | C11: 10 | D11: C015 | E11: 43731 | F11: hikvision | G11: 3 | H11: gtcAdmin15 | I11: qwerty | J11: qwerty | K11: CAMERA 3 NO VIDEO. STOCK ROOM. FOR VISIT | L11: ONLINE | M11: FOR VISIT | N11: 44120 | O11: Macarling, Federico | P11: TTHOCH | Q11: - | R11: M001170038 | S11: 44120.459 | T11: NOT MONITORED
A12: Area 1 (MP) | B12: Mobitek Xentro Mall Vigan | C12: 10 | D12: C089 | E12: 32874 | F12: HIKVISION | G12: 4 | H12: gtcAdmin | I12: GUANZON_C89 | J12: 48208923646 | K12: offline to hikconnect | L12: OFFLINE | M12: RECORDING | N12: 44159 | O12: Macarling, Federico | P12: 123456 | Q12: n/a | R12: M001170038 | S12: 44159.583 | T12: MONITORED
A13: Area 1 (MP) | B13: OPPO - Xentro Mall Vigan | C13: 10 | D13: C067 | E13: 43731 | F13: hikvision | G13: 3 | H13: gtcAdmin67 | I13: qwerty | J13: 48206723646 | K13: Good and online | L13: ONLINE | M13: RECORDING | N13: 44120 | O13: Macarling, Federico | P13: 123456 | Q13: - | R13: M001170038 | S13: 44120.46 | T13: NOT MONITORED
A14: Area 1 (MP) | B14: Samsung - Nepo Mall Dagupan | C14: 10 | D14: C058 | E14: 43731 | F14: hikvision | G14: 3 | H14: gtcAdmin58 | I14: qwerty | J14: qwerty | K14: RETURNED DVR ORIGINAL - OK | L14: ONLINE | M14: RECORDING | N14: 44120 | O14: Macarling, Federico | P14: 123456 | Q14: - | R14: M001170038 | S14: 44120.46 | T14: NOT MONITORED
A15: Area 1 (MP) | B15: Samsung - SM Center Dagupan | C15: 10 | D15: C086 | E15: 43466 | F15: HIKVISION | G15: 3 | H15: gtcAdmin86 | I15: SAMSUNG_C086 | J15: samsung48208623646 | K15: CAM 1 AND CAM 2 - NO VIDEO - FOR VISIT | L15: OFFLINE | M15: FOR VISIT | N15: 44159 | O15: Macarling, Federico | P15: 123456 | Q15: NO | R15: M001170038 | S15: 44159.583 | T15: MONITORED
A16: Area 1 (MP) | B16: Samsung - Vigan | C16: 10 | D16: C040 | E16: 43663 | F16: hikvision | G16: 4 | H16: gtcAdmin40 | I16: qwerty | J16: 48204023646 | K16: need router to enable hik connect online | L16: OFFLINE | M16: FOR VISIT | N16: 44120 | O16: Macarling, Federico | P16: 123456 | Q16: - | R16: M001170038 | S16: 44120.462 | T16: NOT MONITORED
A17: Area 2 (MP) | B17: Huawei - Magic Mall 2 San Carlos | C17: 11 | D17: C080 | E17: 32874 | F17: HIKVISION | G17: 3 | H17: gtcAdmin80 | I17: qwerty | J17: 1234 | K17: good. 3 camera installed only | L17: ONLINE | M17: RECORDING | N17: 44120 | O17: Macarling, Federico | P17: 123456 | Q17: - | R17: M001170038 | S17: 44120.464 | T17: NOT MONITORED
A18: Area 2 (MP) | B18: Huawei - Robinson Calasiao | C18: 11 | D18: C078 | E18: 43466 | F18: Hikvision | G18: 4 | H18: gtcAdmin78 | I18: qwerty | J18: G48207823646 | K18: good and online | L18: ONLINE | M18: RECORDING | N18: 44120 | O18: Macarling, Federico | P18: 123456 | Q18: n/a | R18: M001170038 | S18: 44120.464 | T18: NOT MONITORED
A19: Area 2 (MP) | B19: Mobitek - Magic Urdaneta - Annex | C19: \N | D19: \N | E19: \N | F19: \N | G19: \N | H19: \N | I19: \N | J19: \N | K19: \N | L19: \N | M19: \N | N19: \N | O19: \N | P19: \N | Q19: \N | R19: \N | S19: \N | T19: NOT YET ADDED
A20: Area 2 (MP) | B20: Mobitek Magic Mall 2 San Carlos | C20: 11 | D20: C082 | E20: 43466 | F20: Hikvision | G20: 4 | H20: gtcAdmin82 | I20: qwerty | J20: 1234 | K20: good and online | L20: ONLINE | M20: RECORDING | N20: 44120 | O20: Macarling, Federico | P20: 123456 | Q20: n/a | R20: M001170038 | S20: 44120.465 | T20: NOT MONITORED
A21: Area 2 (MP) | B21: Mobitek Magic San Carlos | C21: 11 | D21: C004 | E21: 43731 | F21: hikvision | G21: 4 | H21: gtcAdmin04 | I21: qwerty | J21: qwerty | K21: PLDT problem no internet - kaya offline and DVR | L21: OFFLINE | M21: RECORDING | N21: 44120 | O21: Macarling, Federico | P21: 123456 | Q21: n/a | R21: M001170038 | S21: 44120.477 | T21: NOT MONITORED
A22: Area 2 (MP) | B22: Mobitek Magic Tayug | C22: 11 | D22: C027 | E22: 43466 | F22: Hikvision | G22: 3 | H22: ggcAdmin27 | I22: qwerty | J22: 1234 | K22: camera 3 - stock room. need to relocate. for visit asap | L22: ONLINE | M22: FOR VISIT | N22: 44120 | O22: Macarling, Federico | P22: 123456 | Q22: - | R22: M001170038 | S22: 44120.466 | T22: NOT MONITORED
A23: Area 2 (MP) | B23: Mobitek Magic Urdaneta | C23: 11 | D23: C006 | E23: 43711 | F23: hikvision | G23: 3 | H23: gtcAdmin06 | I23: qwerty | J23: 48200623646 | K23: Good and online | L23: ONLINE | M23: RECORDING | N23: 44120 | O23: Macarling, Federico | P23: SYMIZF | Q23: - | R23: M001170038 | S23: 44120.471 | T23: NOT MONITORED
A24: Area 2 (MP) | B24: Mobitek Robinson Calasiao | C24: 11 | D24: C035 | E24: 43466 | F24: DVR-DVS | G24: 4 | H24: gtcAdmin35 | I24: qwerty | J24: 1234 | K24: good and online | L24: ONLINE | M24: RECORDING | N24: 44120 | O24: Macarling, Federico | P24: 123456 | Q24: - | R24: M001170038 | S24: 44120.473 | T24: NOT MONITORED
A25: Area 2 (MP) | B25: Mobitek Royal Mall Bayambang | C25: 11 | D25: C029 | E25: 43466 | F25: Hikvision | G25: 3 | H25: gtcAdmin29 | I25: GUANZON_WIFI_C029 | J25: mobitek4820292019 | K25: dvr for replacement. can't add to hikconnect | L25: OFFLINE | M25: FOR VISIT | N25: 44120 | O25: Macarling, Federico | P25: ZRFFXP | Q25: - | R25: M001170038 | S25: 44120.475 | T25: NOT MONITORED
A26: Area 2 (MP) | B26: Mobitek San Carlos Town Center | C26: 11 | D26: C068 | E26: 43466 | F26: Hikvision | G26: 3 | H26: gtcAdmin68 | I26: qwerty | J26: G48206823646C068 | K26: good and online | L26: ONLINE | M26: GOOD | N26: 44120 | O26: Macarling, Federico | P26: 123456 | Q26: n/a | R26: M001170038 | S26: 44120.476 | T26: NOT MONITORED
A27: Area 2 (MP) | B27: Mobitek SM Rosales | C27: 11 | D27: C020 | E27: 43466 | F27: EXPOSE | G27: 3 | H27: ggcAdmin20 | I27: qwerty | J27: 1234 | K27: Good and online | L27: ONLINE | M27: RECORDING | N27: 44120 | O27: Macarling, Federico | P27: 123456 | Q27: n/a | R27: M001170038 | S27: 44120.476 | T27: NOT MONITORED
A28: Area 2 (MP) | B28: Oppo - Magic Urdaneta - Annex | C28: \N | D28: \N | E28: \N | F28: \N | G28: \N | H28: \N | I28: \N | J28: \N | K28: \N | L28: \N | M28: \N | N28: \N | O28: \N | P28: \N | Q28: \N | R28: \N | S28: \N | T28: NOT YET ADDED
A29: Area 2 (MP) | B29: OPPO - Robinsons Calasiao | C29: 11 | D29: C050 | E29: 43466 | F29: DVR-DVS | G29: 3 | H29: gtcAdmin50 | I29: qwerty | J29: 1234 | K29: camera 3 and camera 4 - NO VIDEO - FOR VISIT | L29: ONLINE | M29: FOR VISIT | N29: 44120 | O29: Macarling, Federico | P29: 123456 | Q29: - | R29: M001170038 | S29: 44120.467 | T29: NOT MONITORED
A30: Area 2 (MP) | B30: Oppo - SM Urdaneta | C30: 11 | D30: C071 | E30: 43466 | F30: Hikvision | G30: 3 | H30: G48223646071 | I30: GUANZON_OPPO_C071 | J30: oppo4820712020 | K30: Good and online | L30: ONLINE | M30: RECORDING | N30: 44120 | O30: Macarling, Federico | P30: 123456 | Q30: - | R30: M001170038 | S30: 44120.475 | T30: NOT MONITORED
A31: Area 2 (MP) | B31: RealMe - Magic Urdaneta - Annex | C31: \N | D31: \N | E31: \N | F31: \N | G31: \N | H31: \N | I31: \N | J31: \N | K31: \N | L31: \N | M31: \N | N31: \N | O31: \N | P31: \N | Q31: \N | R31: \N | S31: \N | T31: NOT YET ADDED
A32: Area 2 (MP) | B32: Samsung - Magic Mall 2 San Carlos | C32: 10 | D32: C081 | E32: 43466 | F32: Hikvision | G32: 4 | H32: gtcAdmin81 | I32: qwerty | J32: 1234 | K32: camera 4 - NO VIDEO - FOR VISIT | L32: ONLINE | M32: RECORDING | N32: 44120 | O32: Macarling, Federico | P32: 123456 | Q32: no | R32: M001170038 | S32: 44120.468 | T32: NOT MONITORED
A33: Area 2 (MP) | B33: Samsung - Magic Urdaneta - Annex | C33: \N | D33: \N | E33: \N | F33: \N | G33: \N | H33: \N | I33: \N | J33: \N | K33: \N | L33: \N | M33: \N | N33: \N | O33: \N | P33: \N | Q33: \N | R33: \N | S33: \N | T33: NOT YET ADDED
A34: Area 2 (MP) | B34: Samsung - Robinson Calasiao | C34: 11 | D34: C036 | E34: 43466 | F34: Hikvision | G34: 4 | H34: G4822364636 | I34: qwerty | J34: 1234 | K34: camera 3 and 4.. for relocation. need to adjuts position. FIX BLIND SPOT | L34: ONLINE | M34: FOR VISIT | N34: 44120 | O34: Macarling, Federico | P34: 123456 | Q34: - | R34: M001170038 | S34: 44120.473 | T34: NOT MONITORED
A35: Area 2 (MP) | B35: Samsung - SM Rosales | C35: 11 | D35: C043 | E35: 43466 | F35: QSEE | G35: 4 | H35: gtcAdmin43 | I35: qwerty | J35: 1234 | K35: Good and online | L35: ONLINE | M35: RECORDING | N35: 44120 | O35: Macarling, Federico | P35: 123456 | Q35: n/a | R35: M001170038 | S35: 44120.474 | T35: NOT MONITORED
A36: Area 2 (MP) | B36: Samsung - SM Urdaneta | C36: 11 | D36: C070 | E36: 43466 | F36: Hikvision | G36: 4 | H36: G48223646070 | I36: qwerty | J36: samsung48207023646 | K36: good and online | L36: ONLINE | M36: RECORDING | N36: 44120 | O36: Macarling, Federico | P36: 123456 | Q36: - | R36: M001170038 | S36: 44120.474 | T36: NOT MONITORED
A37: Area 2 (MP) | B37: Vivo - SM Urdaneta | C37: 11 | D37: C072 | E37: 43466 | F37: Hikvision | G37: 3 | H37: G48223646072 | I37: qwrtty | J37: 1234 | K37: good. 3camera installed already | L37: ONLINE | M37: RECORDING | N37: 44120 | O37: Macarling, Federico | P37: 123456 | Q37: - | R37: M001170038 | S37: 44131.57 | T37: NOT MONITORED
A38: Area 3 (MP) | B38: Huawei - Iba Town Center | C38: 12 | D38: C083 | E38: 43731 | F38: hikvision | G38: 4 | H38: gtcAdmin83 | I38: PLDTMyDSLBizGUANZON_HUAWEI | J38: G48208323646 | K38: cam 1 and cashier area need to adjust. pldt problem no internet due to unpaid bills | L38: OFFLINE | M38: FOR VISIT | N38: 44120 | O38: Macarling, Federico | P38: 123456 | Q38: n/a | R38: M001170038 | S38: 44120.496 | T38: NOT MONITORED
A39: Area 3 (MP) | B39: Mobitek City Mall Dau | C39: 12 | D39: C064 | E39: 43749 | F39: hikvision | G39: 4 | H39: gtcAdmin64 | I39: qwerty | J39: qwerty | K39: Good and online | L39: ONLINE | M39: RECORDING | N39: 44120 | O39: Macarling, Federico | P39: 123456 | Q39: N/A | R39: M001170038 | S39: 44120.485 | T39: NOT MONITORED
A40: Area 3 (MP) | B40: Mobitek Iba Town Center | C40: 12 | D40: C042 | E40: 43466 | F40: Hikvision | G40: 4 | H40: gtcAdmin42 | I40: qwerty | J40: G48204223646 | K40: offline due to unpaid bills @ PLDT | L40: OFFLINE | M40: RECORDING | N40: 44120 | O40: Macarling, Federico | P40: 123456 | Q40: - | R40: M001170038 | S40: 44120.497 | T40: NOT MONITORED
...
